Workbook
Name GIL: הנחות!$F$2:$G$8
Name GIL: [1]חברים!$AV$6:$AW$12
Name GIL: חברים!$AU$6:$AV$12

Sheet חברים
AC1: =SUM(HEVARIM[בר מצוה]) -> 317464.62 | AE1: =SUM(HEVARIM[בת מצוה]) -> 318566.92 | AF1: =SUM(HEVARIM[מענק חתונה]) -> 11016157 | AI1: =SUM(HEVARIM[מענק לימודים]) -> 14163943 | AM1: =SUM(HEVARIM[דמי עזיבה 25 שנות ותק]) -> 2176001.6 | AO1: =SUM(HEVARIM[דמי עזיבה לגיל 65]) -> 2685494.3
AB2: מגיל | AC2: ='תקציבים מיוחדים'!E5 -> 0 | AE2: ='תקציבים מיוחדים'!E5 -> 0 | AF2: ='תקציבים מיוחדים'!E6 -> 0 | AI2: ='תקציבים מיוחדים'!E7 -> 0
AB3: עד גיל | AC3: ='תקציבים מיוחדים'!F5 -> 13 | AE3: ='תקציבים מיוחדים'!F5 -> 13 | AF3: ='תקציבים מיוחדים'!F6 -> 21 | AI3: ='תקציבים מיוחדים'!F7 -> 21 | AR3: =SUM(HEVARIM[צביעה]) -> 508125
AB4: סכום | AC4: ='תקציבים מיוחדים'!D5 -> 7165 | AE4: ='תקציבים מיוחדים'!D5 -> 7165 | AF4: ='תקציבים מיוחדים'!D6 -> 60512.5 | AI4: ='תקציבים מיוחדים'!D7 -> 105588.5
A5: קוד חבר | B5: שם | C5: שם משפחה | D5: פרטי | E5: מין | F5: תאריך לידה | G5: גיל | H5: קוד תקציב | I5: תאור תקציב | J5: מצב תקציב | K5: קבוצת תקציב | L5: תעודת זהות | M5: מספר משפחה | N5: משפחה | O5: מצב משפחתי | P5: קוד מעמד | Q5: מעמד | R5: תאריך מעמד | S5: מצב משפחתי2 | T5: קוד תקציב משפחה מקורי | U5: קבוצת חינוך | V5: סיווג לנקודת זיכוי | W5: קצבת זיקנה בניכוי בריאות | X5: פנסיה | Y5: שארים | Z5: לספירה לתקציבים מיוחדים | AA5: בקרה לריכוז | AB5: בר מצוה | AC5: בר מצווה שנה | AD5: בת מצוה | AE5: בת מצווה שנה | AF5: מענק חתונה | AG5: חתונה שנה | AH5: מענק לימודים | AI5: לימוד שנה | AJ5: בקרה | AK5: ותק מחברה 40 | AL5: דמי עזיבה 25 שנות ותק | AM5: דמי עזיבה 25 שנה | AN5: דמי עזיבה לגיל 65 | AO5: דמי עזיבה 65 שנה | AP5: ותק הורים | AQ5: בקרת ותק הורים מול גיל ילד | AR5: צביעה | AS5: צביעה שנה | AU5: קבוצת חינוך
A6: 01022 | B6: אלדד שולמית פנינה | C6: אלדד | D6: שולמית פנינה | E6: נ | F6: 36624 | G6: 25 | H6: 0102 | I6: אלדד רוניאל | J6: פתוח | K6: תושב לגביה | L6: 211500681 | M6: 01021 | N6: אלדד רוניאל | O6: =IFERROR(VLOOKUP(HEVARIM[[#This Row],[קוד תקציב]],[2]תקציבים!A:L,6,0),0) -> 0 | P6: 6 | Q6: תושב-בר רשות | R6: 45536 | S6: נשוי | T6: 0115 | U6: =VLOOKUP(HEVARIM[[#This Row],[גיל]],GIL,2,1) -> -- | V6: =IF(HEVARIM[[#This Row],[קוד מעמד]]="4 ",IF(HEVARIM[[#This Row],[גיל]]=1,1,IF(HEVARIM[[#This Row],[גיל]]<=5,5,18)),"") | W6: =IF(G6<67,0, IF(O6=1, IF(G6>=80,1896-231,1795-231), IF(O6=2, IF(G6>=80,2899-332,2697-332), 0)) ) -> 0 | X6: =IF(AND(HEVARIM[[#This Row],[מין]]="ז ",HEVARIM[[#This Row],[גיל]]>67),'[2]ריכוז נתונים'!$AB$2,IF(AND(HEVARIM[[#This Row],[מין]]="נ ",HEVARIM[[#This Row],[גיל]]>62),'[2]ריכוז נתונים'!$AB$2,0)) -> 0 | Y6: =IF(HEVARIM[[#This Row],[מצב משפחתי2]]="אלמן",'[2]ריכוז נתונים'!$AC$2,0) -> 0 | Z6: =VLOOKUP(VALUE(HEVARIM[[#This Row],[קוד מעמד]]),הנחות!$I$2:$K$21,3,0) -> 0 | AA6: =ISERROR(VLOOKUP(HEVARIM[[#This Row],[קוד תקציב]],'[2]ריכוז נתונים'!A:A,1,0)) -> TRUE | AB6: =IF(AND($G6>=AC$2,$G6<=AC$3,$E6="ז ",$Z6=1),AC$4*(($G6-AC$2)/(AC$3-AC$2)),0) -> 0 | AC6: =IF(HEVARIM[[#This Row],[בר מצוה]]>0,YEAR(TODAY())+'תקציבים מיוחדים'!$F$5-HEVARIM[[#This Row],[גיל]],0) -> 0 | AD6: =IF(AND($G6>=AE$2,$G6<=AE$3,$E6="נ ",$Z6=1),AE$4*(($G6-AE$2)/(AE$3-AE$2)),0) -> 0 | AE6: =IF(HEVARIM[[#This Row],[בת מצוה]]>0,YEAR(TODAY())+'תקציבים מיוחדים'!$F$5-HEVARIM[[#This Row],[גיל]],0) -> 0 | AF6: =IF(AND($S6>="רווק",$Z6=1),AF$4*IF(HEVARIM[[#This Row],[גיל]]>$AF$3,1,(($G6-AF$2)/(AF$3-AF$2))),0) -> 0 | AG6: =IF(HEVARIM[[#This Row],[מענק חתונה]]>0,IF(HEVARIM[[#This Row],[גיל]]>'תקציבים מיוחדים'!$F$6,2025,YEAR(TODAY())+'תקציבים מיוחדים'!$F$6-HEVARIM[[#This Row],[גיל]]),0) -> 0 | AH6: =IF(AND($G6>=AI$2,$G6<=AI$3,$Z6=1),AI$4*(($G6-AI$2)/(AI$3-AI$2)),0) -> 0 | AI6: =IF(AH6>0,YEAR(TODAY())+'תקציבים מיוחדים'!$F$7-HEVARIM[[#This Row],[גיל]],0) -> 0 | AJ6: =IF(AND(ISERROR(VLOOKUP(H6,'[2]ריכוז נתונים'!A:L,1,0)),P6="1 "),1,0) -> 0 | AK6: =IF(VALUE(HEVARIM[[#This Row],[קוד מעמד]])=1,VLOOKUP((IF(LEFT(HEVARIM[[#This Row],[קוד חבר]],1)="0",HEVARIM[[#This Row],[קוד חבר]],VALUE(HEVARIM[[#This Row],[קוד חבר]]))),'ותק חברה 40'!AQ:AW,7,0),"") | AL6: =IF(AND(VALUE(HEVARIM[[#This Row],[קוד מעמד]])=1,HEVARIM[[#This Row],[ותק מחברה 40]]<25),HEVARIM[[#This Row],[ותק מחברה 40]]/25*הנחות!$C$4,0) -> 0 | AM6: =IF(HEVARIM[[#This Row],[דמי עזיבה 25 שנות ותק]]>0,YEAR(TODAY())+24-ROUNDDOWN(HEVARIM[[#This Row],[ותק מחברה 40]],0),"") | AN6: =IF(AND(VALUE(HEVARIM[[#This Row],[קוד מעמד]])=1,HEVARIM[[#This Row],[ותק מחברה 40]]>25,HEVARIM[[#This Row],[גיל]]<65),הנחות!$C$14+(HEVARIM[[#This Row],[ותק מחברה 40]]-25)*הנחות!$C$10*0.25,0) -> 0 | AO6: =IF(HEVARIM[[#This Row],[דמי עזיבה לגיל 65]]>0,YEAR(TODAY())+64-ROUNDDOWN(HEVARIM[[#This Row],[גיל]],0),"") | AP6: =SUMIF(HEVARIM[קוד תקציב],HEVARIM[[#This Row],[קוד תקציב משפחה מקורי]],HEVARIM[ותק מחברה 40]) -> 82.19 | AQ6: =IF(AND(HEVARIM[[#This Row],[גיל]]>HEVARIM[[#This Row],[ותק הורים]],OR(HEVARIM[[#This Row],[בר מצוה]]>0,HEVARIM[[#This Row],[בת מצוה]]>0,HEVARIM[[#This Row],[מענק חתונה]]>0,HEVARIM[[#This Row],[מענק לימודים]]>0)),1,0) -> 0 | AR6: =IF(HEVARIM[[#This Row],[קוד מעמד]]="1 ",IFERROR(VLOOKUP(HEVARIM[[#This Row],[קוד תקציב]],'תקציב צביעה - לקראת השינוי'!A:F,6,0),0)/COUNTIFS(HEVARIM[קוד תקציב],HEVARIM[[#This Row],[קוד תקציב]],HEVARIM[קוד מעמד],"1 "),0) -> 0 | AS6: =IF(HEVARIM[[#This Row],[קוד מעמד]]="1 ",IFERROR(VLOOKUP(HEVARIM[[#This Row],[קוד תקציב]],'תקציב צביעה - לקראת השינוי'!A:F,4,0),0),0) -> 0 | AU6: 0 | AV6: פעוט
A7: 01023 | B7: אלדד קדם איתן | C7: אלדד | D7: קדם איתן | E7: ז | F7: 44533 | G7: 4 | H7: 0102 | I7: אלדד רוניאל | J7: פתוח | K7: תושב לגביה | L7: 234321297 | M7: 01021 | N7: אלדד רוניאל | O7: =IFERROR(VLOOKUP(HEVARIM[[#This Row],[קוד תקציב]],[2]תקציבים!A:L,6,0),0) -> 0 | P7: 17 | Q7: ילד תושב | R7: 45536 | S7: רווק | T7: 0115 | U7: =VLOOKUP(HEVARIM[[#This Row],[גיל]],GIL,2,1) -> גנים | V7: =IF(HEVARIM[[#This Row],[קוד מעמד]]="4 ",IF(HEVARIM[[#This Row],[גיל]]=1,1,IF(HEVARIM[[#This Row],[גיל]]<=5,5,18)),"") | W7: =IF(G7<67,0, IF(O7=1, IF(G7>=80,1896-231,1795-231), IF(O7=2, IF(G7>=80,2899-332,2697-332), 0)) ) -> 0 | X7: =IF(AND(HEVARIM[[#This Row],[מין]]="ז ",HEVARIM[[#This Row],[גיל]]>67),'[2]ריכוז נתונים'!$AB$2,IF(AND(HEVARIM[[#This Row],[מין]]="נ ",HEVARIM[[#This Row],[גיל]]>62),'[2]ריכוז נתונים'!$AB$2,0)) -> 0 | Y7: =IF(HEVARIM[[#This Row],[מצב משפחתי2]]="אלמן",'[2]ריכוז נתונים'!$AC$2,0) -> 0 | Z7: =VLOOKUP(VALUE(HEVARIM[[#This Row],[קוד מעמד]]),הנחות!$I$2:$K$21,3,0) -> 0 | AA7: =ISERROR(VLOOKUP(HEVARIM[[#This Row],[קוד תקציב]],'[2]ריכוז נתונים'!A:A,1,0)) -> TRUE | AB7: =IF(AND($G7>=AC$2,$G7<=AC$3,$E7="ז ",$Z7=1),AC$4*(($G7-AC$2)/(AC$3-AC$2)),0) -> 0 | AC7: =IF(HEVARIM[[#This Row],[בר מצוה]]>0,YEAR(TODAY())+'תקציבים מיוחדים'!$F$5-HEVARIM[[#This Row],[גיל]],0) -> 0 | AD7: =IF(AND($G7>=AE$2,$G7<=AE$3,$E7="נ ",$Z7=1),AE$4*(($G7-AE$2)/(AE$3-AE$2)),0) -> 0 | AE7: =IF(HEVARIM[[#This Row],[בת מצוה]]>0,YEAR(TODAY())+'תקציבים מיוחדים'!$F$5-HEVARIM[[#This Row],[גיל]],0) -> 0 | AF7: =IF(AND($S7>="רווק",$Z7=1),AF$4*IF(HEVARIM[[#This Row],[גיל]]>$AF$3,1,(($G7-AF$2)/(AF$3-AF$2))),0) -> 0 | AG7: =IF(HEVARIM[[#This Row],[מענק חתונה]]>0,IF(HEVARIM[[#This Row],[גיל]]>'תקציבים מיוחדים'!$F$6,2025,YEAR(TODAY())+'תקציבים מיוחדים'!$F$6-HEVARIM[[#This Row],[גיל]]),0) -> 0 | AH7: =IF(AND($G7>=AI$2,$G7<=AI$3,$Z7=1),AI$4*(($G7-AI$2)/(AI$3-AI$2)),0) -> 0 | AI7: =IF(AH7>0,YEAR(TODAY())+'תקציבים מיוחדים'!$F$7-HEVARIM[[#This Row],[גיל]],0) -> 0 | AJ7: =IF(AND(ISERROR(VLOOKUP(H7,'[2]ריכוז נתונים'!A:L,1,0)),P7="1 "),1,0) -> 0 | AK7: =IF(VALUE(HEVARIM[[#This Row],[קוד מעמד]])=1,VLOOKUP((IF(LEFT(HEVARIM[[#This Row],[קוד חבר]],1)="0",HEVARIM[[#This Row],[קוד חבר]],VALUE(HEVARIM[[#This Row],[קוד חבר]]))),'ותק חברה 40'!AQ:AW,7,0),"") | AL7: =IF(AND(VALUE(HEVARIM[[#This Row],[קוד מעמד]])=1,HEVARIM[[#This Row],[ותק מחברה 40]]<25),HEVARIM[[#This Row],[ותק מחברה 40]]/25*הנחות!$C$4,0) -> 0 | AM7: =IF(HEVARIM[[#This Row],[דמי עזיבה 25 שנות ותק]]>0,YEAR(TODAY())+25-ROUNDDOWN(HEVARIM[[#This Row],[ותק מחברה 40]],0),"") | AN7: =IF(AND(VALUE(HEVARIM[[#This Row],[קוד מעמד]])=1,HEVARIM[[#This Row],[ותק מחברה 40]]>25,HEVARIM[[#This Row],[גיל]]<65),הנחות!$C$14+(HEVARIM[[#This Row],[ותק מחברה 40]]-25)*הנחות!$C$10*0.25,0) -> 0 | AO7: =IF(HEVARIM[[#This Row],[דמי עזיבה לגיל 65]]>0,YEAR(TODAY())+64-ROUNDDOWN(HEVARIM[[#This Row],[גיל]],0),"") | AP7: =SUMIF(HEVARIM[קוד תקציב],HEVARIM[[#This Row],[קוד תקציב משפחה מקורי]],HEVARIM[ותק מחברה 40]) -> 82.19 | AQ7: =IF(AND(HEVARIM[[#This Row],[גיל]]>HEVARIM[[#This Row],[ותק הורים]],OR(HEVARIM[[#This Row],[בר מצוה]]>0,HEVARIM[[#This Row],[בת מצוה]]>0,HEVARIM[[#This Row],[מענק חתונה]]>0,HEVARIM[[#This Row],[מענק לימודים]]>0)),1,0) -> 0 | AR7: =IF(HEVARIM[[#This Row],[קוד מעמד]]="1 ",IFERROR(VLOOKUP(HEVARIM[[#This Row],[קוד תקציב]],'תקציב צביעה - לקראת השינוי'!A:F,6,0),0)/COUNTIFS(HEVARIM[קוד תקציב],HEVARIM[[#This Row],[קוד תקציב]],HEVARIM[קוד מעמד],"1 "),0) -> 0 | AS7: =IF(HEVARIM[[#This Row],[קוד מעמד]]="1 ",IFERROR(VLOOKUP(HEVARIM[[#This Row],[קוד תקציב]],'תקציב צביעה - לקראת השינוי'!A:F,4,0),0),0) -> 0 | AU7: 3 | AV7: גנים
A8: 01024 | B8: אלדד שקד הודי | C8: אלדד | D8: שקד הודי | E8: נ | F8: 45389 | G8: 1 | H8: 0102 | I8: אלדד רוניאל | J8: פתוח | K8: תושב לגביה | L8: 238742696 | M8: 01021 | N8: אלדד רוניאל | O8: =IFERROR(VLOOKUP(HEVARIM[[#This Row],[קוד תקציב]],[2]תקציבים!A:L,6,0),0) -> 0 | P8: 17 | Q8: ילד תושב | R8: 45536 | S8: רווק | T8: 0115 | U8: =VLOOKUP(HEVARIM[[#This Row],[גיל]],GIL,2,1) -> פעוט | V8: =IF(HEVARIM[[#This Row],[קוד מעמד]]="4 ",IF(HEVARIM[[#This Row],[גיל]]=1,1,IF(HEVARIM[[#This Row],[גיל]]<=5,5,18)),"") | W8: =IF(G8<67,0, IF(O8=1, IF(G8>=80,1896-231,1795-231), IF(O8=2, IF(G8>=80,2899-332,2697-332), 0)) ) -> 0 | X8: =IF(AND(HEVARIM[[#This Row],[מין]]="ז ",HEVARIM[[#This Row],[גיל]]>67),'[2]ריכוז נתונים'!$AB$2,IF(AND(HEVARIM[[#This Row],[מין]]="נ ",HEVARIM[[#This Row],[גיל]]>62),'[2]ריכוז נתונים'!$AB$2,0)) -> 0 | Y8: =IF(HEVARIM[[#This Row],[מצב משפחתי2]]="אלמן",'[2]ריכוז נתונים'!$AC$2,0) -> 0 | Z8: =VLOOKUP(VALUE(HEVARIM[[#This Row],[קוד מעמד]]),הנחות!$I$2:$K$21,3,0) -> 0 | AA8: =ISERROR(VLOOKUP(HEVARIM[[#This Row],[קוד תקציב]],'[2]ריכוז נתונים'!A:A,1,0)) -> TRUE | AB8: =IF(AND($G8>=AC$2,$G8<=AC$3,$E8="ז ",$Z8=1),AC$4*(($G8-AC$2)/(AC$3-AC$2)),0) -> 0 | AC8: =IF(HEVARIM[[#This Row],[בר מצוה]]>0,YEAR(TODAY())+'תקציבים מיוחדים'!$F$5-HEVARIM[[#This Row],[גיל]],0) -> 0 | AD8: =IF(AND($G8>=AE$2,$G8<=AE$3,$E8="נ ",$Z8=1),AE$4*(($G8-AE$2)/(AE$3-AE$2)),0) -> 0 | AE8: =IF(HEVARIM[[#This Row],[בת מצוה]]>0,YEAR(TODAY())+'תקציבים מיוחדים'!$F$5-HEVARIM[[#This Row],[גיל]],0) -> 0 | AF8: =IF(AND($S8>="רווק",$Z8=1),AF$4*IF(HEVARIM[[#This Row],[גיל]]>$AF$3,1,(($G8-AF$2)/(AF$3-AF$2))),0) -> 0 | AG8: =IF(HEVARIM[[#This Row],[מענק חתונה]]>0,IF(HEVARIM[[#This Row],[גיל]]>'תקציבים מיוחדים'!$F$6,2025,YEAR(TODAY())+'תקציבים מיוחדים'!$F$6-HEVARIM[[#This Row],[גיל]]),0) -> 0 | AH8: =IF(AND($G8>=AI$2,$G8<=AI$3,$Z8=1),AI$4*(($G8-AI$2)/(AI$3-AI$2)),0) -> 0 | AI8: =IF(AH8>0,YEAR(TODAY())+'תקציבים מיוחדים'!$F$7-HEVARIM[[#This Row],[גיל]],0) -> 0 | AJ8: =IF(AND(ISERROR(VLOOKUP(H8,'[2]ריכוז נתונים'!A:L,1,0)),P8="1 "),1,0) -> 0 | AK8: =IF(VALUE(HEVARIM[[#This Row],[קוד מעמד]])=1,VLOOKUP((IF(LEFT(HEVARIM[[#This Row],[קוד חבר]],1)="0",HEVARIM[[#This Row],[קוד חבר]],VALUE(HEVARIM[[#This Row],[קוד חבר]]))),'ותק חברה 40'!AQ:AW,7,0),"") | AL8: =IF(AND(VALUE(HEVARIM[[#This Row],[קוד מעמד]])=1,HEVARIM[[#This Row],[ותק מחברה 40]]<25),HEVARIM[[#This Row],[ותק מחברה 40]]/25*הנחות!$C$4,0) -> 0 | AM8: =IF(HEVARIM[[#This Row],[דמי עזיבה 25 שנות ותק]]>0,YEAR(TODAY())+25-ROUNDDOWN(HEVARIM[[#This Row],[ותק מחברה 40]],0),"") | AN8: =IF(AND(VALUE(HEVARIM[[#This Row],[קוד מעמד]])=1,HEVARIM[[#This Row],[ותק מחברה 40]]>25,HEVARIM[[#This Row],[גיל]]<65),הנחות!$C$14+(HEVARIM[[#This Row],[ותק מחברה 40]]-25)*הנחות!$C$10*0.25,0) -> 0 | AO8: =IF(HEVARIM[[#This Row],[דמי עזיבה לגיל 65]]>0,YEAR(TODAY())+64-ROUNDDOWN(HEVARIM[[#This Row],[גיל]],0),"") | AP8: =SUMIF(HEVARIM[קוד תקציב],HEVARIM[[#This Row],[קוד תקציב משפחה מקורי]],HEVARIM[ותק מחברה 40]) -> 82.19 | AQ8: =IF(AND(HEVARIM[[#This Row],[גיל]]>HEVARIM[[#This Row],[ותק הורים]],OR(HEVARIM[[#This Row],[בר מצוה]]>0,HEVARIM[[#This Row],[בת מצוה]]>0,HEVARIM[[#This Row],[מענק חתונה]]>0,HEVARIM[[#This Row],[מענק לימודים]]>0)),1,0) -> 0 | AR8: =IF(HEVARIM[[#This Row],[קוד מעמד]]="1 ",IFERROR(VLOOKUP(HEVARIM[[#This Row],[קוד תקציב]],'תקציב צביעה - לקראת השינוי'!A:F,6,0),0)/COUNTIFS(HEVARIM[קוד תקציב],HEVARIM[[#This Row],[קוד תקציב]],HEVARIM[קוד מעמד],"1 "),0) -> 0 | AS8: =IF(HEVARIM[[#This Row],[קוד מעמד]]="1 ",IFERROR(VLOOKUP(HEVARIM[[#This Row],[קוד תקציב]],'תקציב צביעה - לקראת השינוי'!A:F,4,0),0),0) -> 0 | AU8: 6 | AV8: יסודי
A9: 01061 | B9: אריאל חנן | C9: אריאל | D9: חנן | E9: ז | F9: 21209 | G9: 67 | H9: 0106 | I9: אריאל חנן וענת | J9: פתוח | K9: חבר | L9: 054998182 | M9: 01061 | N9: אריאל חנן | O9: =IFERROR(VLOOKUP(HEVARIM[[#This Row],[קוד תקציב]],[2]תקציבים!A:L,6,0),0) -> 2 | P9: 1 | Q9: חבר ^חבר | R9: 31291 | S9: נשוי | T9: 0103 | U9: =VLOOKUP(HEVARIM[[#This Row],[גיל]],GIL,2,1) -> -- | V9: =IF(HEVARIM[[#This Row],[קוד מעמד]]="4 ",IF(HEVARIM[[#This Row],[גיל]]=1,1,IF(HEVARIM[[#This Row],[גיל]]<=5,5,18)),"") | W9: =IF(G9<67,0, IF(O9=1, IF(G9>=80,1896-231,1795-231), IF(O9=2, IF(G9>=80,2899-332,2697-332), 0)) ) -> 2365 | X9: =IF(AND(HEVARIM[[#This Row],[מין]]="ז ",HEVARIM[[#This Row],[גיל]]>67),'[2]ריכוז נתונים'!$AB$2,IF(AND(HEVARIM[[#This Row],[מין]]="נ ",HEVARIM[[#This Row],[גיל]]>62),'[2]ריכוז נתונים'!$AB$2,0)) -> 0 | Y9: =IF(HEVARIM[[#This Row],[מצב משפחתי2]]="אלמן",'[2]ריכוז נתונים'!$AC$2,0) -> 0 | Z9: =VLOOKUP(VALUE(HEVARIM[[#This Row],[קוד מעמד]]),הנחות!$I$2:$K$21,3,0) -> 0 | AA9: =ISERROR(VLOOKUP(HEVARIM[[#This Row],[קוד תקציב]],'[2]ריכוז נתונים'!A:A,1,0)) -> FALSE | AB9: =IF(AND($G9>=AC$2,$G9<=AC$3,$E9="ז ",$Z9=1),AC$4*(($G9-AC$2)/(AC$3-AC$2)),0) -> 0 | AC9: =IF(HEVARIM[[#This Row],[בר מצוה]]>0,YEAR(TODAY())+'תקציבים מיוחדים'!$F$5-HEVARIM[[#This Row],[גיל]],0) -> 0 | AD9: =IF(AND($G9>=AE$2,$G9<=AE$3,$E9="נ ",$Z9=1),AE$4*(($G9-AE$2)/(AE$3-AE$2)),0) -> 0 | AE9: =IF(HEVARIM[[#This Row],[בת מצוה]]>0,YEAR(TODAY())+'תקציבים מיוחדים'!$F$5-HEVARIM[[#This Row],[גיל]],0) -> 0 | AF9: =IF(AND($S9>="רווק",$Z9=1),AF$4*IF(HEVARIM[[#This Row],[גיל]]>$AF$3,1,(($G9-AF$2)/(AF$3-AF$2))),0) -> 0 | AG9: =IF(HEVARIM[[#This Row],[מענק חתונה]]>0,IF(HEVARIM[[#This Row],[גיל]]>'תקציבים מיוחדים'!$F$6,2025,YEAR(TODAY())+'תקציבים מיוחדים'!$F$6-HEVARIM[[#This Row],[גיל]]),0) -> 0 | AH9: =IF(AND($G9>=AI$2,$G9<=AI$3,$Z9=1),AI$4*(($G9-AI$2)/(AI$3-AI$2)),0) -> 0 | AI9: =IF(AH9>0,YEAR(TODAY())+'תקציבים מיוחדים'!$F$7-HEVARIM[[#This Row],[גיל]],0) -> 0 | AJ9: =IF(AND(ISERROR(VLOOKUP(H9,'[2]ריכוז נתונים'!A:L,1,0)),P9="1 "),1,0) -> 0 | AK9: =IF(VALUE(HEVARIM[[#This Row],[קוד מעמד]])=1,VLOOKUP((IF(LEFT(HEVARIM[[#This Row],[קוד חבר]],1)="0",HEVARIM[[#This Row],[קוד חבר]],VALUE(HEVARIM[[#This Row],[קוד חבר]]))),'ותק חברה 40'!AQ:AW,7,0),"") -> 47.53 | AL9: =IF(AND(VALUE(HEVARIM[[#This Row],[קוד מעמד]])=1,HEVARIM[[#This Row],[ותק מחברה 40]]<25),HEVARIM[[#This Row],[ותק מחברה 40]]/25*הנחות!$C$4,0) -> 0 | AM9: =IF(HEVARIM[[#This Row],[דמי עזיבה 25 שנות ותק]]>0,YEAR(TODAY())+25-ROUNDDOWN(HEVARIM[[#This Row],[ותק מחברה 40]],0),"") | AN9: =IF(AND(VALUE(HEVARIM[[#This Row],[קוד מעמד]])=1,HEVARIM[[#This Row],[ותק מחברה 40]]>25,HEVARIM[[#This Row],[גיל]]<65),הנחות!$C$14+(HEVARIM[[#This Row],[ותק מחברה 40]]-25)*הנחות!$C$10*0.25,0) -> 0 | AO9: =IF(HEVARIM[[#This Row],[דמי עזיבה לגיל 65]]>0,YEAR(TODAY())+64-ROUNDDOWN(HEVARIM[[#This Row],[גיל]],0),"") | AP9: =SUMIF(HEVARIM[קוד תקציב],HEVARIM[[#This Row],[קוד תקציב משפחה מקורי]],HEVARIM[ותק מחברה 40]) -> 0 | AQ9: =IF(AND(HEVARIM[[#This Row],[גיל]]>HEVARIM[[#This Row],[ותק הורים]],OR(HEVARIM[[#This Row],[בר מצוה]]>0,HEVARIM[[#This Row],[בת מצוה]]>0,HEVARIM[[#This Row],[מענק חתונה]]>0,HEVARIM[[#This Row],[מענק לימודים]]>0)),1,0) -> 0 | AR9: =IF(HEVARIM[[#This Row],[קוד מעמד]]="1 ",IFERROR(VLOOKUP(HEVARIM[[#This Row],[קוד תקציב]],'תקציב צביעה - לקראת השינוי'!A:F,6,0),0)/COUNTIFS(HEVARIM[קוד תקציב],HEVARIM[[#This Row],[קוד תקציב]],HEVARIM[קוד מעמד],"1 "),0) -> 1406.25 | AS9: =IF(HEVARIM[[#This Row],[קוד מעמד]]="1 ",IFERROR(VLOOKUP(HEVARIM[[#This Row],[קוד תקציב]],'תקציב צביעה - לקראת השינוי'!A:F,4,0),0),0) -> 2032 | AU9: 13 | AV9: חטיבה
A10: 01122 | B10: אלירז עפרה | C10: אלירז | D10: עפרה | E10: נ | F10: 20037 | G10: 71 | H10: 0112 | I10: אלירז שמואל ועפרה | J10: פתוח | K10: חבר | L10: 052823911 | M10: 01121 | N10: אלירז שמואל | O10: =IFERROR(VLOOKUP(HEVARIM[[#This Row],[קוד תקציב]],[2]תקציבים!A:L,6,0),0) -> 2 | P10: 1 | Q10: חבר ^חבר | R10: 39336 | S10: נשוי | T10: 0103 | U10: =VLOOKUP(HEVARIM[[#This Row],[גיל]],GIL,2,1) -> -- | V10: =IF(HEVARIM[[#This Row],[קוד מעמד]]="4 ",IF(HEVARIM[[#This Row],[גיל]]=1,1,IF(HEVARIM[[#This Row],[גיל]]<=5,5,18)),"") | W10: =IF(G10<67,0, IF(O10=1, IF(G10>=80,1896-231,1795-231), IF(O10=2, IF(G10>=80,2899-332,2697-332), 0)) ) -> 2365 | X10: =IF(AND(HEVARIM[[#This Row],[מין]]="ז ",HEVARIM[[#This Row],[גיל]]>67),'[2]ריכוז נתונים'!$AB$2,IF(AND(HEVARIM[[#This Row],[מין]]="נ ",HEVARIM[[#This Row],[גיל]]>62),'[2]ריכוז נתונים'!$AB$2,0)) -> 7500 | Y10: =IF(HEVARIM[[#This Row],[מצב משפחתי2]]="אלמן",'[2]ריכוז נתונים'!$AC$2,0) -> 0 | Z10: =VLOOKUP(VALUE(HEVARIM[[#This Row],[קוד מעמד]]),הנחות!$I$2:$K$21,3,0) -> 0 | AA10: =ISERROR(VLOOKUP(HEVARIM[[#This Row],[קוד תקציב]],'[2]ריכוז נתונים'!A:A,1,0)) -> FALSE | AB10: =IF(AND($G10>=AC$2,$G10<=AC$3,$E10="ז ",$Z10=1),AC$4*(($G10-AC$2)/(AC$3-AC$2)),0) -> 0 | AC10: =IF(HEVARIM[[#This Row],[בר מצוה]]>0,YEAR(TODAY())+'תקציבים מיוחדים'!$F$5-HEVARIM[[#This Row],[גיל]],0) -> 0 | AD10: =IF(AND($G10>=AE$2,$G10<=AE$3,$E10="נ ",$Z10=1),AE$4*(($G10-AE$2)/(AE$3-AE$2)),0) -> 0 | AE10: =IF(HEVARIM[[#This Row],[בת מצוה]]>0,YEAR(TODAY())+'תקציבים מיוחדים'!$F$5-HEVARIM[[#This Row],[גיל]],0) -> 0 | AF10: =IF(AND($S10>="רווק",$Z10=1),AF$4*IF(HEVARIM[[#This Row],[גיל]]>$AF$3,1,(($G10-AF$2)/(AF$3-AF$2))),0) -> 0 | AG10: =IF(HEVARIM[[#This Row],[מענק חתונה]]>0,IF(HEVARIM[[#This Row],[גיל]]>'תקציבים מיוחדים'!$F$6,2025,YEAR(TODAY())+'תקציבים מיוחדים'!$F$6-HEVARIM[[#This Row],[גיל]]),0) -> 0 | AH10: =IF(AND($G10>=AI$2,$G10<=AI$3,$Z10=1),AI$4*(($G10-AI$2)/(AI$3-AI$2)),0) -> 0 | AI10: =IF(AH10>0,YEAR(TODAY())+'תקציבים מיוחדים'!$F$7-HEVARIM[[#This Row],[גיל]],0) -> 0 | AJ10: =IF(AND(ISERROR(VLOOKUP(H10,'[2]ריכוז נתונים'!A:L,1,0)),P10="1 "),1,0) -> 0 | AK10: =IF(VALUE(HEVARIM[[#This Row],[קוד מעמד]])=1,VLOOKUP((IF(LEFT(HEVARIM[[#This Row],[קוד חבר]],1)="0",HEVARIM[[#This Row],[קוד חבר]],VALUE(HEVARIM[[#This Row],[קוד חבר]]))),'ותק חברה 40'!AQ:AW,7,0),"") -> 48 | AL10: =IF(AND(VALUE(HEVARIM[[#This Row],[קוד מעמד]])=1,HEVARIM[[#This Row],[ותק מחברה 40]]<25),HEVARIM[[#This Row],[ותק מחברה 40]]/25*הנחות!$C$4,0) -> 0 | AM10: =IF(HEVARIM[[#This Row],[דמי עזיבה 25 שנות ותק]]>0,YEAR(TODAY())+25-ROUNDDOWN(HEVARIM[[#This Row],[ותק מחברה 40]],0),"") | AN10: =IF(AND(VALUE(HEVARIM[[#This Row],[קוד מעמד]])=1,HEVARIM[[#This Row],[ותק מחברה 40]]>25,HEVARIM[[#This Row],[גיל]]<65),הנחות!$C$14+(HEVARIM[[#This Row],[ותק מחברה 40]]-25)*הנחות!$C$10*0.25,0) -> 0 | AO10: =IF(HEVARIM[[#This Row],[דמי עזיבה לגיל 65]]>0,YEAR(TODAY())+64-ROUNDDOWN(HEVARIM[[#This Row],[גיל]],0),"") | AP10: =SUMIF(HEVARIM[קוד תקציב],HEVARIM[[#This Row],[קוד תקציב משפחה מקורי]],HEVARIM[ותק מחברה 40]) -> 0 | AQ10: =IF(AND(HEVARIM[[#This Row],[גיל]]>HEVARIM[[#This Row],[ותק הורים]],OR(HEVARIM[[#This Row],[בר מצוה]]>0,HEVARIM[[#This Row],[בת מצוה]]>0,HEVARIM[[#This Row],[מענק חתונה]]>0,HEVARIM[[#This Row],[מענק לימודים]]>0)),1,0) -> 0 | AR10: =IF(HEVARIM[[#This Row],[קוד מעמד]]="1 ",IFERROR(VLOOKUP(HEVARIM[[#This Row],[קוד תקציב]],'תקציב צביעה - לקראת השינוי'!A:F,6,0),0)/COUNTIFS(HEVARIM[קוד תקציב],HEVARIM[[#This Row],[קוד תקציב]],HEVARIM[קוד מעמד],"1 "),0) -> 2812.5 | AS10: =IF(HEVARIM[[#This Row],[קוד מעמד]]="1 ",IFERROR(VLOOKUP(HEVARIM[[#This Row],[קוד תקציב]],'תקציב צביעה - לקראת השינוי'!A:F,4,0),0),0) -> 2029 | AU10: 15 | AV10: תיכון
A11: 01151 | B11: אלדד נפתלי | C11: אלדד | D11: נפתלי | E11: ז | F11: 22791 | G11: 63 | H11: 0115 | I11: אלדד נפתלי ומאשי | J11: פתוח | K11: חבר | L11: 057457699 | M11: 01151 | N11: אלדד נפתלי | O11: =IFERROR(VLOOKUP(HEVARIM[[#This Row],[קוד תקציב]],[2]תקציבים!A:L,6,0),0) -> 2 | P11: 1 | Q11: חבר ^חבר | R11: 31944 | S11: נשוי | T11: 0105 | U11: =VLOOKUP(HEVARIM[[#This Row],[גיל]],GIL,2,1) -> -- | V11: =IF(HEVARIM[[#This Row],[קוד מעמד]]="4 ",IF(HEVARIM[[#This Row],[גיל]]=1,1,IF(HEVARIM[[#This Row],[גיל]]<=5,5,18)),"") | W11: =IF(G11<67,0, IF(O11=1, IF(G11>=80,1896-231,1795-231), IF(O11=2, IF(G11>=80,2899-332,2697-332), 0)) ) -> 0 | X11: =IF(AND(HEVARIM[[#This Row],[מין]]="ז ",HEVARIM[[#This Row],[גיל]]>67),'[2]ריכוז נתונים'!$AB$2,IF(AND(HEVARIM[[#This Row],[מין]]="נ ",HEVARIM[[#This Row],[גיל]]>62),'[2]ריכוז נתונים'!$AB$2,0)) -> 0 | Y11: =IF(HEVARIM[[#This Row],[מצב משפחתי2]]="אלמן",'[2]ריכוז נתונים'!$AC$2,0) -> 0 | Z11: =VLOOKUP(VALUE(HEVARIM[[#This Row],[קוד מעמד]]),הנחות!$I$2:$K$21,3,0) -> 0 | AA11: =ISERROR(VLOOKUP(HEVARIM[[#This Row],[קוד תקציב]],'[2]ריכוז נתונים'!A:A,1,0)) -> FALSE | AB11: =IF(AND($G11>=AC$2,$G11<=AC$3,$E11="ז ",$Z11=1),AC$4*(($G11-AC$2)/(AC$3-AC$2)),0) -> 0 | AC11: =IF(HEVARIM[[#This Row],[בר מצוה]]>0,YEAR(TODAY())+'תקציבים מיוחדים'!$F$5-HEVARIM[[#This Row],[גיל]],0) -> 0 | AD11: =IF(AND($G11>=AE$2,$G11<=AE$3,$E11="נ ",$Z11=1),AE$4*(($G11-AE$2)/(AE$3-AE$2)),0) -> 0 | AE11: =IF(HEVARIM[[#This Row],[בת מצוה]]>0,YEAR(TODAY())+'תקציבים מיוחדים'!$F$5-HEVARIM[[#This Row],[גיל]],0) -> 0 | AF11: =IF(AND($S11>="רווק",$Z11=1),AF$4*IF(HEVARIM[[#This Row],[גיל]]>$AF$3,1,(($G11-AF$2)/(AF$3-AF$2))),0) -> 0 | AG11: =IF(HEVARIM[[#This Row],[מענק חתונה]]>0,IF(HEVARIM[[#This Row],[גיל]]>'תקציבים מיוחדים'!$F$6,2025,YEAR(TODAY())+'תקציבים מיוחדים'!$F$6-HEVARIM[[#This Row],[גיל]]),0) -> 0 | AH11: =IF(AND($G11>=AI$2,$G11<=AI$3,$Z11=1),AI$4*(($G11-AI$2)/(AI$3-AI$2)),0) -> 0 | AI11: =IF(AH11>0,YEAR(TODAY())+'תקציבים מיוחדים'!$F$7-HEVARIM[[#This Row],[גיל]],0) -> 0 | AJ11: =IF(AND(ISERROR(VLOOKUP(H11,'[2]ריכוז נתונים'!A:L,1,0)),P11="1 "),1,0) -> 0 | AK11: =IF(VALUE(HEVARIM[[#This Row],[קוד מעמד]])=1,VLOOKUP((IF(LEFT(HEVARIM[[#This Row],[קוד חבר]],1)="0",HEVARIM[[#This Row],[קוד חבר]],VALUE(HEVARIM[[#This Row],[קוד חבר]]))),'ותק חברה 40'!AQ:AW,7,0),"") -> 43.95 | AL11: =IF(AND(VALUE(HEVARIM[[#This Row],[קוד מעמד]])=1,HEVARIM[[#This Row],[ותק מחברה 40]]<25),HEVARIM[[#This Row],[ותק מחברה 40]]/25*הנחות!$C$4,0) -> 0 | AM11: =IF(HEVARIM[[#This Row],[דמי עזיבה 25 שנות ותק]]>0,YEAR(TODAY())+25-ROUNDDOWN(HEVARIM[[#This Row],[ותק מחברה 40]],0),"") | AN11: =IF(AND(VALUE(HEVARIM[[#This Row],[קוד מעמד]])=1,HEVARIM[[#This Row],[ותק מחברה 40]]>25,HEVARIM[[#This Row],[גיל]]<65),הנחות!$C$14+(HEVARIM[[#This Row],[ותק מחברה 40]]-25)*הנחות!$C$10*0.25,0) -> 77616.217 | AO11: =IF(HEVARIM[[#This Row],[דמי עזיבה לגיל 65]]>0,YEAR(TODAY())+64-ROUNDDOWN(HEVARIM[[#This Row],[גיל]],0),"") -> 2027 | AP11: =SUMIF(HEVARIM[קוד תקציב],HEVARIM[[#This Row],[קוד תקציב משפחה מקורי]],HEVARIM[ותק מחברה 40]) -> 0 | AQ11: =IF(AND(HEVARIM[[#This Row],[גיל]]>HEVARIM[[#This Row],[ותק הורים]],OR(HEVARIM[[#This Row],[בר מצוה]]>0,HEVARIM[[#This Row],[בת מצוה]]>0,HEVARIM[[#This Row],[מענק חתונה]]>0,HEVARIM[[#This Row],[מענק לימודים]]>0)),1,0) -> 0 | AR11: =IF(HEVARIM[[#This Row],[קוד מעמד]]="1 ",IFERROR(VLOOKUP(HEVARIM[[#This Row],[קוד תקציב]],'תקציב צביעה - לקראת השינוי'!A:F,6,0),0)/COUNTIFS(HEVARIM[קוד תקציב],HEVARIM[[#This Row],[קוד תקציב]],HEVARIM[קוד מעמד],"1 "),0) -> 3281.25 | AS11: =IF(HEVARIM[[#This Row],[קוד מעמד]]="1 ",IFERROR(VLOOKUP(HEVARIM[[#This Row],[קוד תקציב]],'תקציב צביעה - לקראת השינוי'!A:F,4,0),0),0) -> 2028 | AU11: 18 | AV11: --
A12: 01211 | B12: אלדד מורדכי | C12: אלדד | D12: מורדכי | E12: ז | F12: 25475 | G12: 56 | H12: 0121 | I12: אלדד מוטי | J12: פתוח | K12: חבר | L12: 024474892 | M12: 01211 | N12: אלדד מורדכי | O12: =IFERROR(VLOOKUP(HEVARIM[[#This Row],[קוד תקציב]],[2]תקציבים!A:L,6,0),0) -> 1 | P12: 1 | Q12: חבר ^חבר | R12: 35995 | S12: גרוש | T12: 0105 | U12: =VLOOKUP(HEVARIM[[#This Row],[גיל]],GIL,2,1) -> -- | V12: =IF(HEVARIM[[#This Row],[קוד מעמד]]="4 ",IF(HEVARIM[[#This Row],[גיל]]=1,1,IF(HEVARIM[[#This Row],[גיל]]<=5,5,18)),"") | W12: =IF(G12<67,0, IF(O12=1, IF(G12>=80,1896-231,1795-231), IF(O12=2, IF(G12>=80,2899-332,2697-332), 0)) ) -> 0 | X12: =IF(AND(HEVARIM[[#This Row],[מין]]="ז ",HEVARIM[[#This Row],[גיל]]>67),'[2]ריכוז נתונים'!$AB$2,IF(AND(HEVARIM[[#This Row],[מין]]="נ ",HEVARIM[[#This Row],[גיל]]>62),'[2]ריכוז נתונים'!$AB$2,0)) -> 0 | Y12: =IF(HEVARIM[[#This Row],[מצב משפחתי2]]="אלמן",'[2]ריכוז נתונים'!$AC$2,0) -> 0 | Z12: =VLOOKUP(VALUE(HEVARIM[[#This Row],[קוד מעמד]]),הנחות!$I$2:$K$21,3,0) -> 0 | AA12: =ISERROR(VLOOKUP(HEVARIM[[#This Row],[קוד תקציב]],'[2]ריכוז נתונים'!A:A,1,0)) -> FALSE | AB12: =IF(AND($G12>=AC$2,$G12<=AC$3,$E12="ז ",$Z12=1),AC$4*(($G12-AC$2)/(AC$3-AC$2)),0) -> 0 | AC12: =IF(HEVARIM[[#This Row],[בר מצוה]]>0,YEAR(TODAY())+'תקציבים מיוחדים'!$F$5-HEVARIM[[#This Row],[גיל]],0) -> 0 | AD12: =IF(AND($G12>=AE$2,$G12<=AE$3,$E12="נ ",$Z12=1),AE$4*(($G12-AE$2)/(AE$3-AE$2)),0) -> 0 | AE12: =IF(HEVARIM[[#This Row],[בת מצוה]]>0,YEAR(TODAY())+'תקציבים מיוחדים'!$F$5-HEVARIM[[#This Row],[גיל]],0) -> 0 | AF12: =IF(AND($S12>="רווק",$Z12=1),AF$4*IF(HEVARIM[[#This Row],[גיל]]>$AF$3,1,(($G12-AF$2)/(AF$3-AF$2))),0) -> 0 | AG12: =IF(HEVARIM[[#This Row],[מענק חתונה]]>0,IF(HEVARIM[[#This Row],[גיל]]>'תקציבים מיוחדים'!$F$6,2025,YEAR(TODAY())+'תקציבים מיוחדים'!$F$6-HEVARIM[[#This Row],[גיל]]),0) -> 0 | AH12: =IF(AND($G12>=AI$2,$G12<=AI$3,$Z12=1),AI$4*(($G12-AI$2)/(AI$3-AI$2)),0) -> 0 | AI12: =IF(AH12>0,YEAR(TODAY())+'תקציבים מיוחדים'!$F$7-HEVARIM[[#This Row],[גיל]],0) -> 0 | AJ12: =IF(AND(ISERROR(VLOOKUP(H12,'[2]ריכוז נתונים'!A:L,1,0)),P12="1 "),1,0) -> 0 | AK12: =IF(VALUE(HEVARIM[[#This Row],[קוד מעמד]])=1,VLOOKUP((IF(LEFT(HEVARIM[[#This Row],[קוד חבר]],1)="0",HEVARIM[[#This Row],[קוד חבר]],VALUE(HEVARIM[[#This Row],[קוד חבר]]))),'ותק חברה 40'!AQ:AW,7,0),"") -> 37.36 | AL12: =IF(AND(VALUE(HEVARIM[[#This Row],[קוד מעמד]])=1,HEVARIM[[#This Row],[ותק מחברה 40]]<25),HEVARIM[[#This Row],[ותק מחברה 40]]/25*הנחות!$C$4,0) -> 0 | AM12: =IF(HEVARIM[[#This Row],[דמי עזיבה 25 שנות ותק]]>0,YEAR(TODAY())+25-ROUNDDOWN(HEVARIM[[#This Row],[ותק מחברה 40]],0),"") | AN12: =IF(AND(VALUE(HEVARIM[[#This Row],[קוד מעמד]])=1,HEVARIM[[#This Row],[ותק מחברה 40]]>25,HEVARIM[[#This Row],[גיל]]<65),הנחות!$C$14+(HEVARIM[[#This Row],[ותק מחברה 40]]-25)*הנחות!$C$10*0.25,0) -> 59948.138 | AO12: =IF(HEVARIM[[#This Row],[דמי עזיבה לגיל 65]]>0,YEAR(TODAY())+64-ROUNDDOWN(HEVARIM[[#This Row],[גיל]],0),"") -> 2034 | AP12: =SUMIF(HEVARIM[קוד תקציב],HEVARIM[[#This Row],[קוד תקציב משפחה מקורי]],HEVARIM[ותק מחברה 40]) -> 0 | AQ12: =IF(AND(HEVARIM[[#This Row],[גיל]]>HEVARIM[[#This Row],[ותק הורים]],OR(HEVARIM[[#This Row],[בר מצוה]]>0,HEVARIM[[#This Row],[בת מצוה]]>0,HEVARIM[[#This Row],[מענק חתונה]]>0,HEVARIM[[#This Row],[מענק לימודים]]>0)),1,0) -> 0 | AR12: =IF(HEVARIM[[#This Row],[קוד מעמד]]="1 ",IFERROR(VLOOKUP(HEVARIM[[#This Row],[קוד תקציב]],'תקציב צביעה - לקראת השינוי'!A:F,6,0),0)/COUNTIFS(HEVARIM[קוד תקציב],HEVARIM[[#This Row],[קוד תקציב]],HEVARIM[קוד מעמד],"1 "),0) -> 0 | AS12: =IF(HEVARIM[[#This Row],[קוד מעמד]]="1 ",IFERROR(VLOOKUP(HEVARIM[[#This Row],[קוד תקציב]],'תקציב צביעה - לקראת השינוי'!A:F,4,0),0),0) -> 0 | AU12: 99 | AV12: Z
A13: 01202 | B13: אריאל נעמה שולמית | C13: אריאל | D13: נעמה שולמית | E13: נ | F13: 37944 | G13: 22 | H13: 0120 | I13: אריאל נעמה | J13: פתוח | K13: חבר | L13: 213195423 | M13: 01202 | N13: אריאל נעמה שולמית | O13: =IFERROR(VLOOKUP(HEVARIM[[#This Row],[קוד תקציב]],[2]תקציבים!A:L,6,0),0) -> 0 | P13: 36 | Q13: מסלול צעירים - זכאי 3/2 ביטוח בריאות | R13: 45505 | S13: רווק | T13: 0106 | U13: =VLOOKUP(HEVARIM[[#This Row],[גיל]],GIL,2,1) -> -- | V13: =IF(HEVARIM[[#This Row],[קוד מעמד]]="4 ",IF(HEVARIM[[#This Row],[גיל]]=1,1,IF(HEVARIM[[#This Row],[גיל]]<=5,5,18)),"") | W13: =IF(G13<67,0, IF(O13=1, IF(G13>=80,1896-231,1795-231), IF(O13=2, IF(G13>=80,2899-332,2697-332), 0)) ) -> 0 | X13: =IF(AND(HEVARIM[[#This Row],[מין]]="ז ",HEVARIM[[#This Row],[גיל]]>67),'[2]ריכוז נתונים'!$AB$2,IF(AND(HEVARIM[[#This Row],[מין]]="נ ",HEVARIM[[#This Row],[גיל]]>62),'[2]ריכוז נתונים'!$AB$2,0)) -> 0 | Y13: =IF(HEVARIM[[#This Row],[מצב משפחתי2]]="אלמן",'[2]ריכוז נתונים'!$AC$2,0) -> 0 | Z13: =VLOOKUP(VALUE(HEVARIM[[#This Row],[קוד מעמד]]),הנחות!$I$2:$K$21,3,0) -> 1 | AA13: =ISERROR(VLOOKUP(HEVARIM[[#This Row],[קוד תקציב]],'[2]ריכוז נתונים'!A:A,1,0)) -> TRUE | AB13: =IF(AND($G13>=AC$2,$G13<=AC$3,$E13="ז ",$Z13=1),AC$4*(($G13-AC$2)/(AC$3-AC$2)),0) -> 0 | AC13: =IF(HEVARIM[[#This Row],[בר מצוה]]>0,YEAR(TODAY())+'תקציבים מיוחדים'!$F$5-HEVARIM[[#This Row],[גיל]],0) -> 0 | AD13: =IF(AND($G13>=AE$2,$G13<=AE$3,$E13="נ ",$Z13=1),AE$4*(($G13-AE$2)/(AE$3-AE$2)),0) -> 0 | AE13: =IF(HEVARIM[[#This Row],[בת מצוה]]>0,YEAR(TODAY())+'תקציבים מיוחדים'!$F$5-HEVARIM[[#This Row],[גיל]],0) -> 0 | AF13: =IF(AND($S13>="רווק",$Z13=1),AF$4*IF(HEVARIM[[#This Row],[גיל]]>$AF$3,1,(($G13-AF$2)/(AF$3-AF$2))),0) -> 60512.5 | AG13: =IF(HEVARIM[[#This Row],[מענק חתונה]]>0,IF(HEVARIM[[#This Row],[גיל]]>'תקציבים מיוחדים'!$F$6,2025,YEAR(TODAY())+'תקציבים מיוחדים'!$F$6-HEVARIM[[#This Row],[גיל]]),0) -> 2025 | AH13: =IF(AND($G13>=AI$2,$G13<=AI$3,$Z13=1),AI$4*(($G13-AI$2)/(AI$3-AI$2)),0) -> 0 | AI13: =IF(AH13>0,YEAR(TODAY())+'תקציבים מיוחדים'!$F$7-HEVARIM[[#This Row],[גיל]],0) -> 0 | AJ13: =IF(AND(ISERROR(VLOOKUP(H13,'[2]ריכוז נתונים'!A:L,1,0)),P13="1 "),1,0) -> 0 | AK13: =IF(VALUE(HEVARIM[[#This Row],[קוד מעמד]])=1,VLOOKUP((IF(LEFT(HEVARIM[[#This Row],[קוד חבר]],1)="0",HEVARIM[[#This Row],[קוד חבר]],VALUE(HEVARIM[[#This Row],[קוד חבר]]))),'ותק חברה 40'!AQ:AW,7,0),"") | AL13: =IF(AND(VALUE(HEVARIM[[#This Row],[קוד מעמד]])=1,HEVARIM[[#This Row],[ותק מחברה 40]]<25),HEVARIM[[#This Row],[ותק מחברה 40]]/25*הנחות!$C$4,0) -> 0 | AM13: =IF(HEVARIM[[#This Row],[דמי עזיבה 25 שנות ותק]]>0,YEAR(TODAY())+25-ROUNDDOWN(HEVARIM[[#This Row],[ותק מחברה 40]],0),"") | AN13: =IF(AND(VALUE(HEVARIM[[#This Row],[קוד מעמד]])=1,HEVARIM[[#This Row],[ותק מחברה 40]]>25,HEVARIM[[#This Row],[גיל]]<65),הנחות!$C$14+(HEVARIM[[#This Row],[ותק מחברה 40]]-25)*הנחות!$C$10*0.25,0) -> 0 | AO13: =IF(HEVARIM[[#This Row],[דמי עזיבה לגיל 65]]>0,YEAR(TODAY())+64-ROUNDDOWN(HEVARIM[[#This Row],[גיל]],0),"") | AP13: =SUMIF(HEVARIM[קוד תקציב],HEVARIM[[#This Row],[קוד תקציב משפחה מקורי]],HEVARIM[ותק מחברה 40]) -> 86.59 | AQ13: =IF(AND(HEVARIM[[#This Row],[גיל]]>HEVARIM[[#This Row],[ותק הורים]],OR(HEVARIM[[#This Row],[בר מצוה]]>0,HEVARIM[[#This Row],[בת מצוה]]>0,HEVARIM[[#This Row],[מענק חתונה]]>0,HEVARIM[[#This Row],[מענק לימודים]]>0)),1,0) -> 0 | AR13: =IF(HEVARIM[[#This Row],[קוד מעמד]]="1 ",IFERROR(VLOOKUP(HEVARIM[[#This Row],[קוד תקציב]],'תקציב צביעה - לקראת השינוי'!A:F,6,0),0)/COUNTIFS(HEVARIM[קוד תקציב],HEVARIM[[#This Row],[קוד תקציב]],HEVARIM[קוד מעמד],"1 "),0) -> 0 | AS13: =IF(HEVARIM[[#This Row],[קוד מעמד]]="1 ",IFERROR(VLOOKUP(HEVARIM[[#This Row],[קוד תקציב]],'תקציב צביעה - לקראת השינוי'!A:F,4,0),0),0) -> 0
A14: 01181 | B14: אריאל אסף | C14: אריאל | D14: אסף | E14: ז | F14: 35211 | G14: 29 | H14: 0118 | I14: אריאל אסף ואלישבע | J14: פתוח | K14: תושב לגביה | L14: 206904666 | M14: 01181 | N14: אריאל אסף | O14: =IFERROR(VLOOKUP(HEVARIM[[#This Row],[קוד תקציב]],[2]תקציבים!A:L,6,0),0) -> 0 | P14: 35 | Q14: מסלול צעירים -עד גיל 03 | R14: 45444 | S14: נשוי | T14: 0106 | U14: =VLOOKUP(HEVARIM[[#This Row],[גיל]],GIL,2,1) -> -- | V14: =IF(HEVARIM[[#This Row],[קוד מעמד]]="4 ",IF(HEVARIM[[#This Row],[גיל]]=1,1,IF(HEVARIM[[#This Row],[גיל]]<=5,5,18)),"") | W14: =IF(G14<67,0, IF(O14=1, IF(G14>=80,1896-231,1795-231), IF(O14=2, IF(G14>=80,2899-332,2697-332), 0)) ) -> 0 | X14: =IF(AND(HEVARIM[[#This Row],[מין]]="ז ",HEVARIM[[#This Row],[גיל]]>67),'[2]ריכוז נתונים'!$AB$2,IF(AND(HEVARIM[[#This Row],[מין]]="נ ",HEVARIM[[#This Row],[גיל]]>62),'[2]ריכוז נתונים'!$AB$2,0)) -> 0 | Y14: =IF(HEVARIM[[#This Row],[מצב משפחתי2]]="אלמן",'[2]ריכוז נתונים'!$AC$2,0) -> 0 | Z14: =VLOOKUP(VALUE(HEVARIM[[#This Row],[קוד מעמד]]),הנחות!$I$2:$K$21,3,0) -> 1 | AA14: =ISERROR(VLOOKUP(HEVARIM[[#This Row],[קוד תקציב]],'[2]ריכוז נתונים'!A:A,1,0)) -> TRUE | AB14: =IF(AND($G14>=AC$2,$G14<=AC$3,$E14="ז ",$Z14=1),AC$4*(($G14-AC$2)/(AC$3-AC$2)),0) -> 0 | AC14: =IF(HEVARIM[[#This Row],[בר מצוה]]>0,YEAR(TODAY())+'תקציבים מיוחדים'!$F$5-HEVARIM[[#This Row],[גיל]],0) -> 0 | AD14: =IF(AND($G14>=AE$2,$G14<=AE$3,$E14="נ ",$Z14=1),AE$4*(($G14-AE$2)/(AE$3-AE$2)),0) -> 0 | AE14: =IF(HEVARIM[[#This Row],[בת מצוה]]>0,YEAR(TODAY())+'תקציבים מיוחדים'!$F$5-HEVARIM[[#This Row],[גיל]],0) -> 0 | AF14: =IF(AND($S14>="רווק",$Z14=1),AF$4*IF(HEVARIM[[#This Row],[גיל]]>$AF$3,1,(($G14-AF$2)/(AF$3-AF$2))),0) -> 0 | AG14: =IF(HEVARIM[[#This Row],[מענק חתונה]]>0,IF(HEVARIM[[#This Row],[גיל]]>'תקציבים מיוחדים'!$F$6,2025,YEAR(TODAY())+'תקציבים מיוחדים'!$F$6-HEVARIM[[#This Row],[גיל]]),0) -> 0 | AH14: =IF(AND($G14>=AI$2,$G14<=AI$3,$Z14=1),AI$4*(($G14-AI$2)/(AI$3-AI$2)),0) -> 0 | AI14: =IF(AH14>0,YEAR(TODAY())+'תקציבים מיוחדים'!$F$7-HEVARIM[[#This Row],[גיל]],0) -> 0 | AJ14: =IF(AND(ISERROR(VLOOKUP(H14,'[2]ריכוז נתונים'!A:L,1,0)),P14="1 "),1,0) -> 0 | AK14: =IF(VALUE(HEVARIM[[#This Row],[קוד מעמד]])=1,VLOOKUP((IF(LEFT(HEVARIM[[#This Row],[קוד חבר]],1)="0",HEVARIM[[#This Row],[קוד חבר]],VALUE(HEVARIM[[#This Row],[קוד חבר]]))),'ותק חברה 40'!AQ:AW,7,0),"") | AL14: =IF(AND(VALUE(HEVARIM[[#This Row],[קוד מעמד]])=1,HEVARIM[[#This Row],[ותק מחברה 40]]<25),HEVARIM[[#This Row],[ותק מחברה 40]]/25*הנחות!$C$4,0) -> 0 | AM14: =IF(HEVARIM[[#This Row],[דמי עזיבה 25 שנות ותק]]>0,YEAR(TODAY())+25-ROUNDDOWN(HEVARIM[[#This Row],[ותק מחברה 40]],0),"") | AN14: =IF(AND(VALUE(HEVARIM[[#This Row],[קוד מעמד]])=1,HEVARIM[[#This Row],[ותק מחברה 40]]>25,HEVARIM[[#This Row],[גיל]]<65),הנחות!$C$14+(HEVARIM[[#This Row],[ותק מחברה 40]]-25)*הנחות!$C$10*0.25,0) -> 0 | AO14: =IF(HEVARIM[[#This Row],[דמי עזיבה לגיל 65]]>0,YEAR(TODAY())+64-ROUNDDOWN(HEVARIM[[#This Row],[גיל]],0),"") | AP14: =SUMIF(HEVARIM[קוד תקציב],HEVARIM[[#This Row],[קוד תקציב משפחה מקורי]],HEVARIM[ותק מחברה 40]) -> 86.59 | AQ14: =IF(AND(HEVARIM[[#This Row],[גיל]]>HEVARIM[[#This Row],[ותק הורים]],OR(HEVARIM[[#This Row],[בר מצוה]]>0,HEVARIM[[#This Row],[בת מצוה]]>0,HEVARIM[[#This Row],[מענק חתונה]]>0,HEVARIM[[#This Row],[מענק לימודים]]>0)),1,0) -> 0 | AR14: =IF(HEVARIM[[#This Row],[קוד מעמד]]="1 ",IFERROR(VLOOKUP(HEVARIM[[#This Row],[קוד תקציב]],'תקציב צביעה - לקראת השינוי'!A:F,6,0),0)/COUNTIFS(HEVARIM[קוד תקציב],HEVARIM[[#This Row],[קוד תקציב]],HEVARIM[קוד מעמד],"1 "),0) -> 0 | AS14: =IF(HEVARIM[[#This Row],[קוד מעמד]]="1 ",IFERROR(VLOOKUP(HEVARIM[[#This Row],[קוד תקציב]],'תקציב צביעה - לקראת השינוי'!A:F,4,0),0),0) -> 0
A15: 01062 | B15: אריאל ענת | C15: אריאל | D15: ענת | E15: נ | F15: 23047 | G15: 62 | H15: 0106 | I15: אריאל חנן וענת | J15: פתוח | K15: חבר | L15: 057874653 | M15: 01061 | N15: אריאל חנן | O15: =IFERROR(VLOOKUP(HEVARIM[[#This Row],[קוד תקציב]],[2]תקציבים!A:L,6,0),0) -> 2 | P15: 1 | Q15: חבר ^חבר | R15: 31594 | S15: נשוי | T15: 0106 | U15: =VLOOKUP(HEVARIM[[#This Row],[גיל]],GIL,2,1) -> -- | V15: =IF(HEVARIM[[#This Row],[קוד מעמד]]="4 ",IF(HEVARIM[[#This Row],[גיל]]=1,1,IF(HEVARIM[[#This Row],[גיל]]<=5,5,18)),"") | W15: =IF(G15<67,0, IF(O15=1, IF(G15>=80,1896-231,1795-231), IF(O15=2, IF(G15>=80,2899-332,2697-332), 0)) ) -> 0 | X15: =IF(AND(HEVARIM[[#This Row],[מין]]="ז ",HEVARIM[[#This Row],[גיל]]>67),'[2]ריכוז נתונים'!$AB$2,IF(AND(HEVARIM[[#This Row],[מין]]="נ ",HEVARIM[[#This Row],[גיל]]>62),'[2]ריכוז נתונים'!$AB$2,0)) -> 0 | Y15: =IF(HEVARIM[[#This Row],[מצב משפחתי2]]="אלמן",'[2]ריכוז נתונים'!$AC$2,0) -> 0 | Z15: =VLOOKUP(VALUE(HEVARIM[[#This Row],[קוד מעמד]]),הנחות!$I$2:$K$21,3,0) -> 0 | AA15: =ISERROR(VLOOKUP(HEVARIM[[#This Row],[קוד תקציב]],'[2]ריכוז נתונים'!A:A,1,0)) -> FALSE | AB15: =IF(AND($G15>=AC$2,$G15<=AC$3,$E15="ז ",$Z15=1),AC$4*(($G15-AC$2)/(AC$3-AC$2)),0) -> 0 | AC15: =IF(HEVARIM[[#This Row],[בר מצוה]]>0,YEAR(TODAY())+'תקציבים מיוחדים'!$F$5-HEVARIM[[#This Row],[גיל]],0) -> 0 | AD15: =IF(AND($G15>=AE$2,$G15<=AE$3,$E15="נ ",$Z15=1),AE$4*(($G15-AE$2)/(AE$3-AE$2)),0) -> 0 | AE15: =IF(HEVARIM[[#This Row],[בת מצוה]]>0,YEAR(TODAY())+'תקציבים מיוחדים'!$F$5-HEVARIM[[#This Row],[גיל]],0) -> 0 | AF15: =IF(AND($S15>="רווק",$Z15=1),AF$4*IF(HEVARIM[[#This Row],[גיל]]>$AF$3,1,(($G15-AF$2)/(AF$3-AF$2))),0) -> 0 | AG15: =IF(HEVARIM[[#This Row],[מענק חתונה]]>0,IF(HEVARIM[[#This Row],[גיל]]>'תקציבים מיוחדים'!$F$6,2025,YEAR(TODAY())+'תקציבים מיוחדים'!$F$6-HEVARIM[[#This Row],[גיל]]),0) -> 0 | AH15: =IF(AND($G15>=AI$2,$G15<=AI$3,$Z15=1),AI$4*(($G15-AI$2)/(AI$3-AI$2)),0) -> 0 | AI15: =IF(AH15>0,YEAR(TODAY())+'תקציבים מיוחדים'!$F$7-HEVARIM[[#This Row],[גיל]],0) -> 0 | AJ15: =IF(AND(ISERROR(VLOOKUP(H15,'[2]ריכוז נתונים'!A:L,1,0)),P15="1 "),1,0) -> 0 | AK15: =IF(VALUE(HEVARIM[[#This Row],[קוד מעמד]])=1,VLOOKUP((IF(LEFT(HEVARIM[[#This Row],[קוד חבר]],1)="0",HEVARIM[[#This Row],[קוד חבר]],VALUE(HEVARIM[[#This Row],[קוד חבר]]))),'ותק חברה 40'!AQ:AW,7,0),"") -> 39.06 | AL15: =IF(AND(VALUE(HEVARIM[[#This Row],[קוד מעמד]])=1,HEVARIM[[#This Row],[ותק מחברה 40]]<25),HEVARIM[[#This Row],[ותק מחברה 40]]/25*הנחות!$C$4,0) -> 0 | AM15: =IF(HEVARIM[[#This Row],[דמי עזיבה 25 שנות ותק]]>0,YEAR(TODAY())+25-ROUNDDOWN(HEVARIM[[#This Row],[ותק מחברה 40]],0),"") | AN15: =IF(AND(VALUE(HEVARIM[[#This Row],[קוד מעמד]])=1,HEVARIM[[#This Row],[ותק מחברה 40]]>25,HEVARIM[[#This Row],[גיל]]<65),הנחות!$C$14+(HEVARIM[[#This Row],[ותק מחברה 40]]-25)*הנחות!$C$10*0.25,0) -> 64505.913 | AO15: =IF(HEVARIM[[#This Row],[דמי עזיבה לגיל 65]]>0,YEAR(TODAY())+64-ROUNDDOWN(HEVARIM[[#This Row],[גיל]],0),"") -> 2028 | AP15: =SUMIF(HEVARIM[קוד תקציב],HEVARIM[[#This Row],[קוד תקציב משפחה מקורי]],HEVARIM[ותק מחברה 40]) -> 86.59 | AQ15: =IF(AND(HEVARIM[[#This Row],[גיל]]>HEVARIM[[#This Row],[ותק הורים]],OR(HEVARIM[[#This Row],[בר מצוה]]>0,HEVARIM[[#This Row],[בת מצוה]]>0,HEVARIM[[#This Row],[מענק חתונה]]>0,HEVARIM[[#This Row],[מענק לימודים]]>0)),1,0) -> 0 | AR15: =IF(HEVARIM[[#This Row],[קוד מעמד]]="1 ",IFERROR(VLOOKUP(HEVARIM[[#This Row],[קוד תקציב]],'תקציב צביעה - לקראת השינוי'!A:F,6,0),0)/COUNTIFS(HEVARIM[קוד תקציב],HEVARIM[[#This Row],[קוד תקציב]],HEVARIM[קוד מעמד],"1 "),0) -> 1406.25 | AS15: =IF(HEVARIM[[#This Row],[קוד מעמד]]="1 ",IFERROR(VLOOKUP(HEVARIM[[#This Row],[קוד תקציב]],'תקציב צביעה - לקראת השינוי'!A:F,4,0),0),0) -> 2032
A16: 01301 | B16: אריאל יאיר | C16: אריאל | D16: יאיר | E16: ז | F16: 31341 | G16: 40 | H16: 0130 | I16: אריאל יאיר ואילת | J16: פתוח | K16: חבר | L16: 038021804 | M16: 01301 | N16: אריאל יאיר | O16: =IFERROR(VLOOKUP(HEVARIM[[#This Row],[קוד תקציב]],[2]תקציבים!A:L,6,0),0) -> 2 | P16: 1 | Q16: חבר ^חבר | R16: 41609 | S16: נשוי | T16: 0106 | U16: =VLOOKUP(HEVARIM[[#This Row],[גיל]],GIL,2,1) -> -- | V16: =IF(HEVARIM[[#This Row],[קוד מעמד]]="4 ",IF(HEVARIM[[#This Row],[גיל]]=1,1,IF(HEVARIM[[#This Row],[גיל]]<=5,5,18)),"") | W16: =IF(G16<67,0, IF(O16=1, IF(G16>=80,1896-231,1795-231), IF(O16=2, IF(G16>=80,2899-332,2697-332), 0)) ) -> 0 | X16: =IF(AND(HEVARIM[[#This Row],[מין]]="ז ",HEVARIM[[#This Row],[גיל]]>67),'[2]ריכוז נתונים'!$AB$2,IF(AND(HEVARIM[[#This Row],[מין]]="נ ",HEVARIM[[#This Row],[גיל]]>62),'[2]ריכוז נתונים'!$AB$2,0)) -> 0 | Y16: =IF(HEVARIM[[#This Row],[מצב משפחתי2]]="אלמן",'[2]ריכוז נתונים'!$AC$2,0) -> 0 | Z16: =VLOOKUP(VALUE(HEVARIM[[#This Row],[קוד מעמד]]),הנחות!$I$2:$K$21,3,0) -> 0 | AA16: =ISERROR(VLOOKUP(HEVARIM[[#This Row],[קוד תקציב]],'[2]ריכוז נתונים'!A:A,1,0)) -> FALSE | AB16: =IF(AND($G16>=AC$2,$G16<=AC$3,$E16="ז ",$Z16=1),AC$4*(($G16-AC$2)/(AC$3-AC$2)),0) -> 0 | AC16: =IF(HEVARIM[[#This Row],[בר מצוה]]>0,YEAR(TODAY())+'תקציבים מיוחדים'!$F$5-HEVARIM[[#This Row],[גיל]],0) -> 0 | AD16: =IF(AND($G16>=AE$2,$G16<=AE$3,$E16="נ ",$Z16=1),AE$4*(($G16-AE$2)/(AE$3-AE$2)),0) -> 0 | AE16: =IF(HEVARIM[[#This Row],[בת מצוה]]>0,YEAR(TODAY())+'תקציבים מיוחדים'!$F$5-HEVARIM[[#This Row],[גיל]],0) -> 0 | AF16: =IF(AND($S16>="רווק",$Z16=1),AF$4*IF(HEVARIM[[#This Row],[גיל]]>$AF$3,1,(($G16-AF$2)/(AF$3-AF$2))),0) -> 0 | AG16: =IF(HEVARIM[[#This Row],[מענק חתונה]]>0,IF(HEVARIM[[#This Row],[גיל]]>'תקציבים מיוחדים'!$F$6,2025,YEAR(TODAY())+'תקציבים מיוחדים'!$F$6-HEVARIM[[#This Row],[גיל]]),0) -> 0 | AH16: =IF(AND($G16>=AI$2,$G16<=AI$3,$Z16=1),AI$4*(($G16-AI$2)/(AI$3-AI$2)),0) -> 0 | AI16: =IF(AH16>0,YEAR(TODAY())+'תקציבים מיוחדים'!$F$7-HEVARIM[[#This Row],[גיל]],0) -> 0 | AJ16: =IF(AND(ISERROR(VLOOKUP(H16,'[2]ריכוז נתונים'!A:L,1,0)),P16="1 "),1,0) -> 0 | AK16: =IF(VALUE(HEVARIM[[#This Row],[קוד מעמד]])=1,VLOOKUP((IF(LEFT(HEVARIM[[#This Row],[קוד חבר]],1)="0",HEVARIM[[#This Row],[קוד חבר]],VALUE(HEVARIM[[#This Row],[קוד חבר]]))),'ותק חברה 40'!AQ:AW,7,0),"") -> 13.76 | AL16: =IF(AND(VALUE(HEVARIM[[#This Row],[קוד מעמד]])=1,HEVARIM[[#This Row],[ותק מחברה 40]]<25),HEVARIM[[#This Row],[ותק מחברה 40]]/25*הנחות!$C$4,0) -> 20659.051 | AM16: =IF(HEVARIM[[#This Row],[דמי עזיבה 25 שנות ותק]]>0,YEAR(TODAY())+25-ROUNDDOWN(HEVARIM[[#This Row],[ותק מחברה 40]],0),"") -> 2038 | AN16: =IF(AND(VALUE(HEVARIM[[#This Row],[קוד מעמד]])=1,HEVARIM[[#This Row],[ותק מחברה 40]]>25,HEVARIM[[#This Row],[גיל]]<65),הנחות!$C$14+(HEVARIM[[#This Row],[ותק מחברה 40]]-25)*הנחות!$C$10*0.25,0) -> 0 | AO16: =IF(HEVARIM[[#This Row],[דמי עזיבה לגיל 65]]>0,YEAR(TODAY())+64-ROUNDDOWN(HEVARIM[[#This Row],[גיל]],0),"") | AP16: =SUMIF(HEVARIM[קוד תקציב],HEVARIM[[#This Row],[קוד תקציב משפחה מקורי]],HEVARIM[ותק מחברה 40]) -> 86.59 | AQ16: =IF(AND(HEVARIM[[#This Row],[גיל]]>HEVARIM[[#This Row],[ותק הורים]],OR(HEVARIM[[#This Row],[בר מצוה]]>0,HEVARIM[[#This Row],[בת מצוה]]>0,HEVARIM[[#This Row],[מענק חתונה]]>0,HEVARIM[[#This Row],[מענק לימודים]]>0)),1,0) -> 0 | AR16: =IF(HEVARIM[[#This Row],[קוד מעמד]]="1 ",IFERROR(VLOOKUP(HEVARIM[[#This Row],[קוד תקציב]],'תקציב צביעה - לקראת השינוי'!A:F,6,0),0)/COUNTIFS(HEVARIM[קוד תקציב],HEVARIM[[#This Row],[קוד תקציב]],HEVARIM[קוד מעמד],"1 "),0) -> 468.75 | AS16: =IF(HEVARIM[[#This Row],[קוד מעמד]]="1 ",IFERROR(VLOOKUP(HEVARIM[[#This Row],[קוד תקציב]],'תקציב צביעה - לקראת השינוי'!A:F,4,0),0),0) -> 2034
A17: 01071 | B17: אורן יהודה | C17: אורן | D17: יהודה | E17: ז | F17: 18890 | G17: 74 | H17: 0107 | I17: אורן יהודה והניה | J17: פתוח | K17: חבר | L17: 051033199 | M17: 01071 | N17: אורן יהודה | O17: =IFERROR(VLOOKUP(HEVARIM[[#This Row],[קוד תקציב]],[2]תקציבים!A:L,6,0),0) -> 2 | P17: 1 | Q17: חבר ^חבר | R17: 26634 | S17: נשוי | T17: 0107 | U17: =VLOOKUP(HEVARIM[[#This Row],[גיל]],GIL,2,1) -> -- | V17: =IF(HEVARIM[[#This Row],[קוד מעמד]]="4 ",IF(HEVARIM[[#This Row],[גיל]]=1,1,IF(HEVARIM[[#This Row],[גיל]]<=5,5,18)),"") | W17: =IF(G17<67,0, IF(O17=1, IF(G17>=80,1896-231,1795-231), IF(O17=2, IF(G17>=80,2899-332,2697-332), 0)) ) -> 2365 | X17: =IF(AND(HEVARIM[[#This Row],[מין]]="ז ",HEVARIM[[#This Row],[גיל]]>67),'[2]ריכוז נתונים'!$AB$2,IF(AND(HEVARIM[[#This Row],[מין]]="נ ",HEVARIM[[#This Row],[גיל]]>62),'[2]ריכוז נתונים'!$AB$2,0)) -> 7500 | Y17: =IF(HEVARIM[[#This Row],[מצב משפחתי2]]="אלמן",'[2]ריכוז נתונים'!$AC$2,0) -> 0 | Z17: =VLOOKUP(VALUE(HEVARIM[[#This Row],[קוד מעמד]]),הנחות!$I$2:$K$21,3,0) -> 0 | AA17: =ISERROR(VLOOKUP(HEVARIM[[#This Row],[קוד תקציב]],'[2]ריכוז נתונים'!A:A,1,0)) -> FALSE | AB17: =IF(AND($G17>=AC$2,$G17<=AC$3,$E17="ז ",$Z17=1),AC$4*(($G17-AC$2)/(AC$3-AC$2)),0) -> 0 | AC17: =IF(HEVARIM[[#This Row],[בר מצוה]]>0,YEAR(TODAY())+'תקציבים מיוחדים'!$F$5-HEVARIM[[#This Row],[גיל]],0) -> 0 | AD17: =IF(AND($G17>=AE$2,$G17<=AE$3,$E17="נ ",$Z17=1),AE$4*(($G17-AE$2)/(AE$3-AE$2)),0) -> 0 | AE17: =IF(HEVARIM[[#This Row],[בת מצוה]]>0,YEAR(TODAY())+'תקציבים מיוחדים'!$F$5-HEVARIM[[#This Row],[גיל]],0) -> 0 | AF17: =IF(AND($S17>="רווק",$Z17=1),AF$4*IF(HEVARIM[[#This Row],[גיל]]>$AF$3,1,(($G17-AF$2)/(AF$3-AF$2))),0) -> 0 | AG17: =IF(HEVARIM[[#This Row],[מענק חתונה]]>0,IF(HEVARIM[[#This Row],[גיל]]>'תקציבים מיוחדים'!$F$6,2025,YEAR(TODAY())+'תקציבים מיוחדים'!$F$6-HEVARIM[[#This Row],[גיל]]),0) -> 0 | AH17: =IF(AND($G17>=AI$2,$G17<=AI$3,$Z17=1),AI$4*(($G17-AI$2)/(AI$3-AI$2)),0) -> 0 | AI17: =IF(AH17>0,YEAR(TODAY())+'תקציבים מיוחדים'!$F$7-HEVARIM[[#This Row],[גיל]],0) -> 0 | AJ17: =IF(AND(ISERROR(VLOOKUP(H17,'[2]ריכוז נתונים'!A:L,1,0)),P17="1 "),1,0) -> 0 | AK17: =IF(VALUE(HEVARIM[[#This Row],[קוד מעמד]])=1,VLOOKUP((IF(LEFT(HEVARIM[[#This Row],[קוד חבר]],1)="0",HEVARIM[[#This Row],[קוד חבר]],VALUE(HEVARIM[[#This Row],[קוד חבר]]))),'ותק חברה 40'!AQ:AW,7,0),"") -> 48 | AL17: =IF(AND(VALUE(HEVARIM[[#This Row],[קוד מעמד]])=1,HEVARIM[[#This Row],[ותק מחברה 40]]<25),HEVARIM[[#This Row],[ותק מחברה 40]]/25*הנחות!$C$4,0) -> 0 | AM17: =IF(HEVARIM[[#This Row],[דמי עזיבה 25 שנות ותק]]>0,YEAR(TODAY())+25-ROUNDDOWN(HEVARIM[[#This Row],[ותק מחברה 40]],0),"") | AN17: =IF(AND(VALUE(HEVARIM[[#This Row],[קוד מעמד]])=1,HEVARIM[[#This Row],[ותק מחברה 40]]>25,HEVARIM[[#This Row],[גיל]]<65),הנחות!$C$14+(HEVARIM[[#This Row],[ותק מחברה 40]]-25)*הנחות!$C$10*0.25,0) -> 0 | AO17: =IF(HEVARIM[[#This Row],[דמי עזיבה לגיל 65]]>0,YEAR(TODAY())+64-ROUNDDOWN(HEVARIM[[#This Row],[גיל]],0),"") | AP17: =SUMIF(HEVARIM[קוד תקציב],HEVARIM[[#This Row],[קוד תקציב משפחה מקורי]],HEVARIM[ותק מחברה 40]) -> 96 | AQ17: =IF(AND(HEVARIM[[#This Row],[גיל]]>HEVARIM[[#This Row],[ותק הורים]],OR(HEVARIM[[#This Row],[בר מצוה]]>0,HEVARIM[[#This Row],[בת מצוה]]>0,HEVARIM[[#This Row],[מענק חתונה]]>0,HEVARIM[[#This Row],[מענק לימודים]]>0)),1,0) -> 0 | AR17: =IF(HEVARIM[[#This Row],[קוד מעמד]]="1 ",IFERROR(VLOOKUP(HEVARIM[[#This Row],[קוד תקציב]],'תקציב צביעה - לקראת השינוי'!A:F,6,0),0)/COUNTIFS(HEVARIM[קוד תקציב],HEVARIM[[#This Row],[קוד תקציב]],HEVARIM[קוד מעמד],"1 "),0) -> 3750 | AS17: =IF(HEVARIM[[#This Row],[קוד מעמד]]="1 ",IFERROR(VLOOKUP(HEVARIM[[#This Row],[קוד תקציב]],'תקציב צביעה - לקראת השינוי'!A:F,4,0),0),0) -> 2027
A18: 01072 | B18: אורן הניה | C18: אורן | D18: הניה | E18: נ | F18: 18979 | G18: 74 | H18: 0107 | I18: אורן יהודה והניה | J18: פתוח | K18: חבר | L18: 050489814 | M18: 01071 | N18: אורן יהודה | O18: =IFERROR(VLOOKUP(HEVARIM[[#This Row],[קוד תקציב]],[2]תקציבים!A:L,6,0),0) -> 2 | P18: 1 | Q18: חבר ^חבר | R18: 26449 | S18: נשוי | T18: 0107 | U18: =VLOOKUP(HEVARIM[[#This Row],[גיל]],GIL,2,1) -> -- | V18: =IF(HEVARIM[[#This Row],[קוד מעמד]]="4 ",IF(HEVARIM[[#This Row],[גיל]]=1,1,IF(HEVARIM[[#This Row],[גיל]]<=5,5,18)),"") | W18: =IF(G18<67,0, IF(O18=1, IF(G18>=80,1896-231,1795-231), IF(O18=2, IF(G18>=80,2899-332,2697-332), 0)) ) -> 2365 | X18: =IF(AND(HEVARIM[[#This Row],[מין]]="ז ",HEVARIM[[#This Row],[גיל]]>67),'[2]ריכוז נתונים'!$AB$2,IF(AND(HEVARIM[[#This Row],[מין]]="נ ",HEVARIM[[#This Row],[גיל]]>62),'[2]ריכוז נתונים'!$AB$2,0)) -> 7500 | Y18: =IF(HEVARIM[[#This Row],[מצב משפחתי2]]="אלמן",'[2]ריכוז נתונים'!$AC$2,0) -> 0 | Z18: =VLOOKUP(VALUE(HEVARIM[[#This Row],[קוד מעמד]]),הנחות!$I$2:$K$21,3,0) -> 0 | AA18: =ISERROR(VLOOKUP(HEVARIM[[#This Row],[קוד תקציב]],'[2]ריכוז נתונים'!A:A,1,0)) -> FALSE | AB18: =IF(AND($G18>=AC$2,$G18<=AC$3,$E18="ז ",$Z18=1),AC$4*(($G18-AC$2)/(AC$3-AC$2)),0) -> 0 | AC18: =IF(HEVARIM[[#This Row],[בר מצוה]]>0,YEAR(TODAY())+'תקציבים מיוחדים'!$F$5-HEVARIM[[#This Row],[גיל]],0) -> 0 | AD18: =IF(AND($G18>=AE$2,$G18<=AE$3,$E18="נ ",$Z18=1),AE$4*(($G18-AE$2)/(AE$3-AE$2)),0) -> 0 | AE18: =IF(HEVARIM[[#This Row],[בת מצוה]]>0,YEAR(TODAY())+'תקציבים מיוחדים'!$F$5-HEVARIM[[#This Row],[גיל]],0) -> 0 | AF18: =IF(AND($S18>="רווק",$Z18=1),AF$4*IF(HEVARIM[[#This Row],[גיל]]>$AF$3,1,(($G18-AF$2)/(AF$3-AF$2))),0) -> 0 | AG18: =IF(HEVARIM[[#This Row],[מענק חתונה]]>0,IF(HEVARIM[[#This Row],[גיל]]>'תקציבים מיוחדים'!$F$6,2025,YEAR(TODAY())+'תקציבים מיוחדים'!$F$6-HEVARIM[[#This Row],[גיל]]),0) -> 0 | AH18: =IF(AND($G18>=AI$2,$G18<=AI$3,$Z18=1),AI$4*(($G18-AI$2)/(AI$3-AI$2)),0) -> 0 | AI18: =IF(AH18>0,YEAR(TODAY())+'תקציבים מיוחדים'!$F$7-HEVARIM[[#This Row],[גיל]],0) -> 0 | AJ18: =IF(AND(ISERROR(VLOOKUP(H18,'[2]ריכוז נתונים'!A:L,1,0)),P18="1 "),1,0) -> 0 | AK18: =IF(VALUE(HEVARIM[[#This Row],[קוד מעמד]])=1,VLOOKUP((IF(LEFT(HEVARIM[[#This Row],[קוד חבר]],1)="0",HEVARIM[[#This Row],[קוד חבר]],VALUE(HEVARIM[[#This Row],[קוד חבר]]))),'ותק חברה 40'!AQ:AW,7,0),"") -> 48 | AL18: =IF(AND(VALUE(HEVARIM[[#This Row],[קוד מעמד]])=1,HEVARIM[[#This Row],[ותק מחברה 40]]<25),HEVARIM[[#This Row],[ותק מחברה 40]]/25*הנחות!$C$4,0) -> 0 | AM18: =IF(HEVARIM[[#This Row],[דמי עזיבה 25 שנות ותק]]>0,YEAR(TODAY())+25-ROUNDDOWN(HEVARIM[[#This Row],[ותק מחברה 40]],0),"") | AN18: =IF(AND(VALUE(HEVARIM[[#This Row],[קוד מעמד]])=1,HEVARIM[[#This Row],[ותק מחברה 40]]>25,HEVARIM[[#This Row],[גיל]]<65),הנחות!$C$14+(HEVARIM[[#This Row],[ותק מחברה 40]]-25)*הנחות!$C$10*0.25,0) -> 0 | AO18: =IF(HEVARIM[[#This Row],[דמי עזיבה לגיל 65]]>0,YEAR(TODAY())+64-ROUNDDOWN(HEVARIM[[#This Row],[גיל]],0),"") | AP18: =SUMIF(HEVARIM[קוד תקציב],HEVARIM[[#This Row],[קוד תקציב משפחה מקורי]],HEVARIM[ותק מחברה 40]) -> 96 | AQ18: =IF(AND(HEVARIM[[#This Row],[גיל]]>HEVARIM[[#This Row],[ותק הורים]],OR(HEVARIM[[#This Row],[בר מצוה]]>0,HEVARIM[[#This Row],[בת מצוה]]>0,HEVARIM[[#This Row],[מענק חתונה]]>0,HEVARIM[[#This Row],[מענק לימודים]]>0)),1,0) -> 0 | AR18: =IF(HEVARIM[[#This Row],[קוד מעמד]]="1 ",IFERROR(VLOOKUP(HEVARIM[[#This Row],[קוד תקציב]],'תקציב צביעה - לקראת השינוי'!A:F,6,0),0)/COUNTIFS(HEVARIM[קוד תקציב],HEVARIM[[#This Row],[קוד תקציב]],HEVARIM[קוד מעמד],"1 "),0) -> 3750 | AS18: =IF(HEVARIM[[#This Row],[קוד מעמד]]="1 ",IFERROR(VLOOKUP(HEVARIM[[#This Row],[קוד תקציב]],'תקציב צביעה - לקראת השינוי'!A:F,4,0),0),0) -> 2027
A19: 03092 | B19: גלבוע נעה | C19: גלבוע | D19: נעה | E19: נ | F19: 31670 | G19: 39 | H19: 0320 | I19: גלבוע נעה | J19: פתוח | K19: חבר | L19: 300007879 | M19: 03092 | N19: גלבוע נעה | O19: =IFERROR(VLOOKUP(HEVARIM[[#This Row],[קוד תקציב]],[2]תקציבים!A:L,6,0),0) -> 1 | P19: 1 | Q19: חבר ^חבר | R19: 39981 | S19: גרוש | T19: 0107 | U19: =VLOOKUP(HEVARIM[[#This Row],[גיל]],GIL,2,1) -> -- | V19: =IF(HEVARIM[[#This Row],[קוד מעמד]]="4 ",IF(HEVARIM[[#This Row],[גיל]]=1,1,IF(HEVARIM[[#This Row],[גיל]]<=5,5,18)),"") | W19: =IF(G19<67,0, IF(O19=1, IF(G19>=80,1896-231,1795-231), IF(O19=2, IF(G19>=80,2899-332,2697-332), 0)) ) -> 0 | X19: =IF(AND(HEVARIM[[#This Row],[מין]]="ז ",HEVARIM[[#This Row],[גיל]]>67),'[2]ריכוז נתונים'!$AB$2,IF(AND(HEVARIM[[#This Row],[מין]]="נ ",HEVARIM[[#This Row],[גיל]]>62),'[2]ריכוז נתונים'!$AB$2,0)) -> 0 | Y19: =IF(HEVARIM[[#This Row],[מצב משפחתי2]]="אלמן",'[2]ריכוז נתונים'!$AC$2,0) -> 0 | Z19: =VLOOKUP(VALUE(HEVARIM[[#This Row],[קוד מעמד]]),הנחות!$I$2:$K$21,3,0) -> 0 | AA19: =ISERROR(VLOOKUP(HEVARIM[[#This Row],[קוד תקציב]],'[2]ריכוז נתונים'!A:A,1,0)) -> FALSE | AB19: =IF(AND($G19>=AC$2,$G19<=AC$3,$E19="ז ",$Z19=1),AC$4*(($G19-AC$2)/(AC$3-AC$2)),0) -> 0 | AC19: =IF(HEVARIM[[#This Row],[בר מצוה]]>0,YEAR(TODAY())+'תקציבים מיוחדים'!$F$5-HEVARIM[[#This Row],[גיל]],0) -> 0 | AD19: =IF(AND($G19>=AE$2,$G19<=AE$3,$E19="נ ",$Z19=1),AE$4*(($G19-AE$2)/(AE$3-AE$2)),0) -> 0 | AE19: =IF(HEVARIM[[#This Row],[בת מצוה]]>0,YEAR(TODAY())+'תקציבים מיוחדים'!$F$5-HEVARIM[[#This Row],[גיל]],0) -> 0 | AF19: =IF(AND($S19>="רווק",$Z19=1),AF$4*IF(HEVARIM[[#This Row],[גיל]]>$AF$3,1,(($G19-AF$2)/(AF$3-AF$2))),0) -> 0 | AG19: =IF(HEVARIM[[#This Row],[מענק חתונה]]>0,IF(HEVARIM[[#This Row],[גיל]]>'תקציבים מיוחדים'!$F$6,2025,YEAR(TODAY())+'תקציבים מיוחדים'!$F$6-HEVARIM[[#This Row],[גיל]]),0) -> 0 | AH19: =IF(AND($G19>=AI$2,$G19<=AI$3,$Z19=1),AI$4*(($G19-AI$2)/(AI$3-AI$2)),0) -> 0 | AI19: =IF(AH19>0,YEAR(TODAY())+'תקציבים מיוחדים'!$F$7-HEVARIM[[#This Row],[גיל]],0) -> 0 | AJ19: =IF(AND(ISERROR(VLOOKUP(H19,'[2]ריכוז נתונים'!A:L,1,0)),P19="1 "),1,0) -> 0 | AK19: =IF(VALUE(HEVARIM[[#This Row],[קוד מעמד]])=1,VLOOKUP((IF(LEFT(HEVARIM[[#This Row],[קוד חבר]],1)="0",HEVARIM[[#This Row],[קוד חבר]],VALUE(HEVARIM[[#This Row],[קוד חבר]]))),'ותק חברה 40'!AQ:AW,7,0),"") -> 18.93 | AL19: =IF(AND(VALUE(HEVARIM[[#This Row],[קוד מעמד]])=1,HEVARIM[[#This Row],[ותק מחברה 40]]<25),HEVARIM[[#This Row],[ותק מחברה 40]]/25*הנחות!$C$4,0) -> 28421.209 | AM19: =IF(HEVARIM[[#This Row],[דמי עזיבה 25 שנות ותק]]>0,YEAR(TODAY())+25-ROUNDDOWN(HEVARIM[[#This Row],[ותק מחברה 40]],0),"") -> 2033 | AN19: =IF(AND(VALUE(HEVARIM[[#This Row],[קוד מעמד]])=1,HEVARIM[[#This Row],[ותק מחברה 40]]>25,HEVARIM[[#This Row],[גיל]]<65),הנחות!$C$14+(HEVARIM[[#This Row],[ותק מחברה 40]]-25)*הנחות!$C$10*0.25,0) -> 0 | AO19: =IF(HEVARIM[[#This Row],[דמי עזיבה לגיל 65]]>0,YEAR(TODAY())+64-ROUNDDOWN(HEVARIM[[#This Row],[גיל]],0),"") | AP19: =SUMIF(HEVARIM[קוד תקציב],HEVARIM[[#This Row],[קוד תקציב משפחה מקורי]],HEVARIM[ותק מחברה 40]) -> 96 | AQ19: =IF(AND(HEVARIM[[#This Row],[גיל]]>HEVARIM[[#This Row],[ותק הורים]],OR(HEVARIM[[#This Row],[בר מצוה]]>0,HEVARIM[[#This Row],[בת מצוה]]>0,HEVARIM[[#This Row],[מענק חתונה]]>0,HEVARIM[[#This Row],[מענק לימודים]]>0)),1,0) -> 0 | AR19: =IF(HEVARIM[[#This Row],[קוד מעמד]]="1 ",IFERROR(VLOOKUP(HEVARIM[[#This Row],[קוד תקציב]],'תקציב צביעה - לקראת השינוי'!A:F,6,0),0)/COUNTIFS(HEVARIM[קוד תקציב],HEVARIM[[#This Row],[קוד תקציב]],HEVARIM[קוד מעמד],"1 "),0) -> 0 | AS19: =IF(HEVARIM[[#This Row],[קוד מעמד]]="1 ",IFERROR(VLOOKUP(HEVARIM[[#This Row],[קוד תקציב]],'תקציב צביעה - לקראת השינוי'!A:F,4,0),0),0) -> 0
A20: 01091 | B20: אמיתי אליעזר | C20: אמיתי | D20: אליעזר | E20: ז | F20: 17399 | G20: 78 | H20: 0109 | I20: אמיתי אליעזר ופרדי | J20: פתוח | K20: חבר | L20: 004606539 | M20: 01091 | N20: אמיתי אליעזר | O20: =IFERROR(VLOOKUP(HEVARIM[[#This Row],[קוד תקציב]],[2]תקציבים!A:L,6,0),0) -> 2 | P20: 1 | Q20: חבר ^חבר | R20: 25203 | S20: נשוי | T20: 0109 | U20: =VLOOKUP(HEVARIM[[#This Row],[גיל]],GIL,2,1) -> -- | V20: =IF(HEVARIM[[#This Row],[קוד מעמד]]="4 ",IF(HEVARIM[[#This Row],[גיל]]=1,1,IF(HEVARIM[[#This Row],[גיל]]<=5,5,18)),"") | W20: =IF(G20<67,0, IF(O20=1, IF(G20>=80,1896-231,1795-231), IF(O20=2, IF(G20>=80,2899-332,2697-332), 0)) ) -> 2365 | X20: =IF(AND(HEVARIM[[#This Row],[מין]]="ז ",HEVARIM[[#This Row],[גיל]]>67),'[2]ריכוז נתונים'!$AB$2,IF(AND(HEVARIM[[#This Row],[מין]]="נ ",HEVARIM[[#This Row],[גיל]]>62),'[2]ריכוז נתונים'!$AB$2,0)) -> 7500 | Y20: =IF(HEVARIM[[#This Row],[מצב משפחתי2]]="אלמן",'[2]ריכוז נתונים'!$AC$2,0) -> 0 | Z20: =VLOOKUP(VALUE(HEVARIM[[#This Row],[קוד מעמד]]),הנחות!$I$2:$K$21,3,0) -> 0 | AA20: =ISERROR(VLOOKUP(HEVARIM[[#This Row],[קוד תקציב]],'[2]ריכוז נתונים'!A:A,1,0)) -> FALSE | AB20: =IF(AND($G20>=AC$2,$G20<=AC$3,$E20="ז ",$Z20=1),AC$4*(($G20-AC$2)/(AC$3-AC$2)),0) -> 0 | AC20: =IF(HEVARIM[[#This Row],[בר מצוה]]>0,YEAR(TODAY())+'תקציבים מיוחדים'!$F$5-HEVARIM[[#This Row],[גיל]],0) -> 0 | AD20: =IF(AND($G20>=AE$2,$G20<=AE$3,$E20="נ ",$Z20=1),AE$4*(($G20-AE$2)/(AE$3-AE$2)),0) -> 0 | AE20: =IF(HEVARIM[[#This Row],[בת מצוה]]>0,YEAR(TODAY())+'תקציבים מיוחדים'!$F$5-HEVARIM[[#This Row],[גיל]],0) -> 0 | AF20: =IF(AND($S20>="רווק",$Z20=1),AF$4*IF(HEVARIM[[#This Row],[גיל]]>$AF$3,1,(($G20-AF$2)/(AF$3-AF$2))),0) -> 0 | AG20: =IF(HEVARIM[[#This Row],[מענק חתונה]]>0,IF(HEVARIM[[#This Row],[גיל]]>'תקציבים מיוחדים'!$F$6,2025,YEAR(TODAY())+'תקציבים מיוחדים'!$F$6-HEVARIM[[#This Row],[גיל]]),0) -> 0 | AH20: =IF(AND($G20>=AI$2,$G20<=AI$3,$Z20=1),AI$4*(($G20-AI$2)/(AI$3-AI$2)),0) -> 0 | AI20: =IF(AH20>0,YEAR(TODAY())+'תקציבים מיוחדים'!$F$7-HEVARIM[[#This Row],[גיל]],0) -> 0 | AJ20: =IF(AND(ISERROR(VLOOKUP(H20,'[2]ריכוז נתונים'!A:L,1,0)),P20="1 "),1,0) -> 0 | AK20: =IF(VALUE(HEVARIM[[#This Row],[קוד מעמד]])=1,VLOOKUP((IF(LEFT(HEVARIM[[#This Row],[קוד חבר]],1)="0",HEVARIM[[#This Row],[קוד חבר]],VALUE(HEVARIM[[#This Row],[קוד חבר]]))),'ותק חברה 40'!AQ:AW,7,0),"") -> 45.73 | AL20: =IF(AND(VALUE(HEVARIM[[#This Row],[קוד מעמד]])=1,HEVARIM[[#This Row],[ותק מחברה 40]]<25),HEVARIM[[#This Row],[ותק מחברה 40]]/25*הנחות!$C$4,0) -> 0 | AM20: =IF(HEVARIM[[#This Row],[דמי עזיבה 25 שנות ותק]]>0,YEAR(TODAY())+25-ROUNDDOWN(HEVARIM[[#This Row],[ותק מחברה 40]],0),"") | AN20: =IF(AND(VALUE(HEVARIM[[#This Row],[קוד מעמד]])=1,HEVARIM[[#This Row],[ותק מחברה 40]]>25,HEVARIM[[#This Row],[גיל]]<65),הנחות!$C$14+(HEVARIM[[#This Row],[ותק מחברה 40]]-25)*הנחות!$C$10*0.25,0) -> 0 | AO20: =IF(HEVARIM[[#This Row],[דמי עזיבה לגיל 65]]>0,YEAR(TODAY())+64-ROUNDDOWN(HEVARIM[[#This Row],[גיל]],0),"") | AP20: =SUMIF(HEVARIM[קוד תקציב],HEVARIM[[#This Row],[קוד תקציב משפחה מקורי]],HEVARIM[ותק מחברה 40]) -> 45.73 | AQ20: =IF(AND(HEVARIM[[#This Row],[גיל]]>HEVARIM[[#This Row],[ותק הורים]],OR(HEVARIM[[#This Row],[בר מצוה]]>0,HEVARIM[[#This Row],[בת מצוה]]>0,HEVARIM[[#This Row],[מענק חתונה]]>0,HEVARIM[[#This Row],[מענק לימודים]]>0)),1,0) -> 0 | AR20: =IF(HEVARIM[[#This Row],[קוד מעמד]]="1 ",IFERROR(VLOOKUP(HEVARIM[[#This Row],[קוד תקציב]],'תקציב צביעה - לקראת השינוי'!A:F,6,0),0)/COUNTIFS(HEVARIM[קוד תקציב],HEVARIM[[#This Row],[קוד תקציב]],HEVARIM[קוד מעמד],"1 "),0) -> 937.5 | AS20: =IF(HEVARIM[[#This Row],[קוד מעמד]]="1 ",IFERROR(VLOOKUP(HEVARIM[[#This Row],[קוד תקציב]],'תקציב צביעה - לקראת השינוי'!A:F,4,0),0),0) -> 2034
A21: 01101 | B21: אדלר מרדכי | C21: אדלר | D21: מרדכי | E21: ז | F21: 19480 | G21: 72 | H21: 0110 | I21: אדלר מרדכי | J21: פתוח | K21: חבר | L21: 051865699 | M21: 01101 | N21: אדלר מרדכי | O21: =IFERROR(VLOOKUP(HEVARIM[[#This Row],[קוד תקציב]],[2]תקציבים!A:L,6,0),0) -> 1 | P21: 1 | Q21: חבר ^חבר | R21: 26298 | S21: גרוש | T21: 0110 | U21: =VLOOKUP(HEVARIM[[#This Row],[גיל]],GIL,2,1) -> -- | V21: =IF(HEVARIM[[#This Row],[קוד מעמד]]="4 ",IF(HEVARIM[[#This Row],[גיל]]=1,1,IF(HEVARIM[[#This Row],[גיל]]<=5,5,18)),"") | W21: =IF(G21<67,0, IF(O21=1, IF(G21>=80,1896-231,1795-231), IF(O21=2, IF(G21>=80,2899-332,2697-332), 0)) ) -> 1564 | X21: =IF(AND(HEVARIM[[#This Row],[מין]]="ז ",HEVARIM[[#This Row],[גיל]]>67),'[2]ריכוז נתונים'!$AB$2,IF(AND(HEVARIM[[#This Row],[מין]]="נ ",HEVARIM[[#This Row],[גיל]]>62),'[2]ריכוז נתונים'!$AB$2,0)) -> 7500 | Y21: =IF(HEVARIM[[#This Row],[מצב משפחתי2]]="אלמן",'[2]ריכוז נתונים'!$AC$2,0) -> 0 | Z21: =VLOOKUP(VALUE(HEVARIM[[#This Row],[קוד מעמד]]),הנחות!$I$2:$K$21,3,0) -> 0 | AA21: =ISERROR(VLOOKUP(HEVARIM[[#This Row],[קוד תקציב]],'[2]ריכוז נתונים'!A:A,1,0)) -> FALSE | AB21: =IF(AND($G21>=AC$2,$G21<=AC$3,$E21="ז ",$Z21=1),AC$4*(($G21-AC$2)/(AC$3-AC$2)),0) -> 0 | AC21: =IF(HEVARIM[[#This Row],[בר מצוה]]>0,YEAR(TODAY())+'תקציבים מיוחדים'!$F$5-HEVARIM[[#This Row],[גיל]],0) -> 0 | AD21: =IF(AND($G21>=AE$2,$G21<=AE$3,$E21="נ ",$Z21=1),AE$4*(($G21-AE$2)/(AE$3-AE$2)),0) -> 0 | AE21: =IF(HEVARIM[[#This Row],[בת מצוה]]>0,YEAR(TODAY())+'תקציבים מיוחדים'!$F$5-HEVARIM[[#This Row],[גיל]],0) -> 0 | AF21: =IF(AND($S21>="רווק",$Z21=1),AF$4*IF(HEVARIM[[#This Row],[גיל]]>$AF$3,1,(($G21-AF$2)/(AF$3-AF$2))),0) -> 0 | AG21: =IF(HEVARIM[[#This Row],[מענק חתונה]]>0,IF(HEVARIM[[#This Row],[גיל]]>'תקציבים מיוחדים'!$F$6,2025,YEAR(TODAY())+'תקציבים מיוחדים'!$F$6-HEVARIM[[#This Row],[גיל]]),0) -> 0 | AH21: =IF(AND($G21>=AI$2,$G21<=AI$3,$Z21=1),AI$4*(($G21-AI$2)/(AI$3-AI$2)),0) -> 0 | AI21: =IF(AH21>0,YEAR(TODAY())+'תקציבים מיוחדים'!$F$7-HEVARIM[[#This Row],[גיל]],0) -> 0 | AJ21: =IF(AND(ISERROR(VLOOKUP(H21,'[2]ריכוז נתונים'!A:L,1,0)),P21="1 "),1,0) -> 0 | AK21: =IF(VALUE(HEVARIM[[#This Row],[קוד מעמד]])=1,VLOOKUP((IF(LEFT(HEVARIM[[#This Row],[קוד חבר]],1)="0",HEVARIM[[#This Row],[קוד חבר]],VALUE(HEVARIM[[#This Row],[קוד חבר]]))),'ותק חברה 40'!AQ:AW,7,0),"") -> 48 | AL21: =IF(AND(VALUE(HEVARIM[[#This Row],[קוד מעמד]])=1,HEVARIM[[#This Row],[ותק מחברה 40]]<25),HEVARIM[[#This Row],[ותק מחברה 40]]/25*הנחות!$C$4,0) -> 0 | AM21: =IF(HEVARIM[[#This Row],[דמי עזיבה 25 שנות ותק]]>0,YEAR(TODAY())+25-ROUNDDOWN(HEVARIM[[#This Row],[ותק מחברה 40]],0),"") | AN21: =IF(AND(VALUE(HEVARIM[[#This Row],[קוד מעמד]])=1,HEVARIM[[#This Row],[ותק מחברה 40]]>25,HEVARIM[[#This Row],[גיל]]<65),הנחות!$C$14+(HEVARIM[[#This Row],[ותק מחברה 40]]-25)*הנחות!$C$10*0.25,0) -> 0 | AO21: =IF(HEVARIM[[#This Row],[דמי עזיבה לגיל 65]]>0,YEAR(TODAY())+64-ROUNDDOWN(HEVARIM[[#This Row],[גיל]],0),"") | AP21: =SUMIF(HEVARIM[קוד תקציב],HEVARIM[[#This Row],[קוד תקציב משפחה מקורי]],HEVARIM[ותק מחברה 40]) -> 48 | AQ21: =IF(AND(HEVARIM[[#This Row],[גיל]]>HEVARIM[[#This Row],[ותק הורים]],OR(HEVARIM[[#This Row],[בר מצוה]]>0,HEVARIM[[#This Row],[בת מצוה]]>0,HEVARIM[[#This Row],[מענק חתונה]]>0,HEVARIM[[#This Row],[מענק לימודים]]>0)),1,0) -> 0 | AR21: =IF(HEVARIM[[#This Row],[קוד מעמד]]="1 ",IFERROR(VLOOKUP(HEVARIM[[#This Row],[קוד תקציב]],'תקציב צביעה - לקראת השינוי'!A:F,6,0),0)/COUNTIFS(HEVARIM[קוד תקציב],HEVARIM[[#This Row],[קוד תקציב]],HEVARIM[קוד מעמד],"1 "),0) -> 2812.5 | AS21: =IF(HEVARIM[[#This Row],[קוד מעמד]]="1 ",IFERROR(VLOOKUP(HEVARIM[[#This Row],[קוד תקציב]],'תקציב צביעה - לקראת השינוי'!A:F,4,0),0),0) -> 2032
